Workbook

Sheet MENSUAL COMERCIALES
A1: 2022 | B1: ENERO | C1: FEBRERO | D1: MARZO | E1: ABRIL | F1: MAYO | G1: JUNIO | H1: JULIO | I1: AGOSTO | J1: SEPTIEMBRE | K1: OCTUBRE | L1: NOVIEMBRE | M1: DICIEMBRE | N1: DICIEMBRE2
A2: ESPIN | B2: 51210 | C2: 107519 | D2: 57374 | E2: 43867 | F2: 29904 | G2: 43063 | H2: 53987 | I2: 23982 | J2: 25568 | K2: 39619 | L2: 34588 | M2: 22344 | N2: =+SUM(B2:M2) -> 533025
A3: LOMBARTE | B3: 2236 | C3: 14216 | D3: 9311 | E3: 7327 | F3: 5195 | G3: 3760 | H3: 9068 | I3: 1877 | J3: 4952 | K3: 6898 | L3: 5047 | M3: 3261 | N3: =+SUM(B3:M3) -> 73148
A4: BEÑAT | B4: 0 | C4: 2492 | D4: 14185 | E4: 3790 | F4: 2576 | G4: 4993 | H4: 2079 | I4: 3586 | J4: 8925 | K4: 7024 | L4: 2198 | M4: 502 | N4: =+SUM(B4:M4) -> 52350
A5: ANTONIO | B5: 796 | C5: 19059 | D5: 16552 | E5: 6899 | F5: 24952 | G5: 7879 | H5: 13434 | I5: 13940 | J5: 4492 | K5: 15225 | L5: 13743 | M5: 7806 | N5: =+SUM(B5:M5) -> 144777
A6: ÁNGEL | B6: 3535 | C6: 32480 | D6: 5674 | E6: 22212 | F6: 9723 | G6: 23041 | H6: 9672 | I6: 4463 | J6: 18975 | K6: 23585 | L6: 14178 | M6: 1743 | N6: =+SUM(B6:M6) -> 169281
A7: CORESUR | B7: 8066 | C7: 13909 | D7: 7463 | E7: 11229 | F7: 9383 | G7: 5668 | H7: 2258 | I7: 5140 | J7: 8405 | K7: 5159 | L7: 3165 | M7: 0 | N7: =+SUM(B7:M7) -> 79845
A8: DM | B8: 4991 | C8: 34922 | D8: 34129 | E8: 11765 | F8: 24961 | G8: 7694 | H8: 15925 | I8: 5270 | J8: 5923 | K8: 12731 | L8: 11452 | M8: 10768 | N8: =+SUM(B8:M8) -> 180531
A9: ONDIVELA | B9: 0 | C9: 0 | D9: 0 | E9: 0 | F9: 0 | G9: 0 | H9: 0 | I9: 0 | J9: 0 | K9: 0 | L9: 0 | M9: 0 | N9: =+SUM(B9:M9) -> 0
N10: =+SUM(B10:M10) -> 0
N11: =+SUM(B11:M11) -> 0
A12: 2023 | B12: ENERO | C12: FEBRERO | D12: MARZO | E12: ABRIL | F12: MAYO | G12: JUNIO | H12: JULIO | I12: AGOSTO | J12: SEPTIEMBRE | K12: OCTUBRE | L12: NOVIEMBRE | M12: DICIEMBRE | N12: =+SUM(B12:M12) -> 0
A13: ESPIN | B13: 48832 | C13: 24511 | D13: 58251 | E13: 16659 | F13: 42496 | G13: 16329 | H13: 34824 | I13: 13051 | J13: 47088 | K13: 41185 | L13: 35806 | M13: 20392 | N13: =+SUM(B13:M13) -> 399424
A14: LOMBARTE | B14: 3555 | C14: 2593 | D14: 15516 | E14: 1042 | F14: 5783 | G14: 12142 | H14: 2961 | I14: 2382 | J14: 4453 | K14: 5684 | L14: 6903 | M14: 7989 | N14: =+SUM(B14:M14) -> 71003
A15: BEÑAT | B15: 7602 | C15: 963 | D15: 10400 | E15: 0 | F15: 1701 | G15: 1510 | H15: 3822 | I15: 1378 | J15: 4637 | K15: 838 | L15: 15019 | M15: 11752 | N15: =+SUM(B15:M15) -> 59622
A16: ANTONIO | B16: 13590 | C16: 6341 | D16: 16428 | E16: 2430 | F16: 7017 | G16: 4760 | H16: 2338 | I16: 17534 | J16: 8900 | K16: 10613 | L16: 7931 | M16: 6701 | N16: =+SUM(B16:M16) -> 104583
A17: ÁNGEL | B17: 30213 | C17: 17859 | D17: 15798 | E17: 14472 | F17: 7832 | G17: 8595 | H17: 10475 | I17: 11027 | J17: 18932 | K17: 17110 | L17: 9368 | M17: 6758 | N17: =+SUM(B17:M17) -> 168439
A18: CORESUR | B18: 6924 | C18: 5435 | D18: 8528 | E18: 2739 | F18: 4227 | G18: 1809 | H18: 7338 | I18: 1686 | J18: 3603 | K18: 2327 | L18: 7805 | M18: 4012 | N18: =+SUM(B18:M18) -> 56433
A19: DM | B19: 13347 | C19: 15566 | D19: 11993 | E19: 2756 | F19: 17225 | G19: 5443 | H19: 3354 | I19: 9417 | J19: 13287 | K19: 11334 | L19: 10914 | M19: 15346 | N19: =+SUM(B19:M19) -> 129982
A20: ONDIVELA | B20: 0 | C20: 0 | D20: 0 | E20: 0 | F20: 0 | G20: 0 | H20: 0 | I20: 0 | J20: 0 | K20: 0 | L20: 0 | M20: 0 | N20: =+SUM(B20:M20) -> 0
N21: =+SUM(B21:M21) -> 0
N22: =+SUM(B22:M22) -> 0
A23: 2024 | B23: ENERO | C23: FEBRERO | D23: MARZO | E23: ABRIL | F23: MAYO | G23: JUNIO | H23: JULIO | I23: AGOSTO | J23: SEPTIEMBRE | K23: OCTUBRE | L23: NOVIEMBRE | M23: DICIEMBRE | N23: =+SUM(B23:M23) -> 0
A24: ESPIN | B24: 39541 | C24: 36619 | D24: 28376 | E24: 47741 | F24: 26198 | G24: 16926 | H24: 21214 | I24: 61772 | J24: 28572 | K24: 40115 | L24: 25901 | M24: 26931 | N24: =+SUM(B24:M24) -> 399906
A25: LOMBARTE | B25: 8151 | C25: 4705 | D25: 3034 | E25: 8913 | F25: 6094 | G25: 1388 | H25: 6521 | I25: 5847 | J25: 7347 | K25: 3640 | L25: 6432 | M25: 3534 | N25: =+SUM(B25:M25) -> 65606
A26: BEÑAT | B26: 249 | C26: 5998 | D26: 0 | E26: 3343 | F26: 3051 | G26: 1210 | H26: 3454 | I26: 10102 | J26: 430 | K26: 1351 | L26: 10940 | M26: 1801 | N26: =+SUM(B26:M26) -> 41929
A27: ANTONIO | B27: 8818 | C27: 4555 | D27: 1884 | E27: 9140 | F27: 11513 | G27: 8794 | H27: 12011 | I27: 10358 | J27: 7891 | K27: 16210 | L27: 3706 | M27: 5495 | N27: =+SUM(B27:M27) -> 100375
A28: ÁNGEL | B28: 20568 | C28: 11815 | D28: 3736 | E28: 8751 | F28: 19594 | G28: 1362 | H28: 6951 | I28: 9826 | J28: 5316 | K28: 11125 | L28: 15303 | M28: 8712 | N28: =+SUM(B28:M28) -> 123059
A29: CORESUR | B29: 6089 | C29: 2994 | D29: 4720 | E29: 7387 | F29: 8357 | G29: 2445 | H29: 2843 | I29: 2457 | J29: 3477 | K29: 6325 | L29: 2758 | M29: 6237 | N29: =+SUM(B29:M29) -> 56089
A30: DM | B30: 5561 | C30: 6461 | D30: 14742 | E30: 16600 | F30: 11344 | G30: 6443 | H30: 5167 | I30: 19446 | J30: 9142 | K30: 9201 | L30: 23005 | M30: 3786 | N30: =+SUM(B30:M30) -> 130898
A31: ONDIVELA | B31: 0 | C31: 6424 | D31: 0 | E31: 249 | F31: 1073 | G31: 0 | H31: 0 | I31: 661 | J31: 3419 | K31: 0 | L31: 4140 | M31: 2869 | N31: =+SUM(B31:M31) -> 18835
N32: =+SUM(B32:M32) -> 0
N33: =+SUM(B33:M33) -> 0
A34: 2025 | B34: ENERO | C34: FEBRERO | D34: MARZO | E34: ABRIL | F34: MAYO | G34: JUNIO | H34: JULIO | I34: AGOSTO | J34: SEPTIEMBRE | K34: OCTUBRE | L34: NOVIEMBRE | M34: DICIEMBRE | N34: =+SUM(B34:M34) -> 0
A35: ESPIN | B35: 55095 | C35: 18042 | D35: 49988 | E35: 22026 | F35: 15704 | G35: 45785 | H35: 35575 | I35: 25780 | J35: 49904 | K35: 24874 | L35: 18960 | M35: 23517 | N35: =+SUM(B35:M35) -> 385250
A36: LOMBARTE | B36: 6320 | C36: 6046 | D36: 10534 | E36: 5162 | F36: 2954 | G36: 7503 | H36: 4708 | I36: 5804 | J36: 9166 | K36: 7131 | L36: 6731 | M36: 4567 | N36: =+SUM(B36:M36) -> 76626
A37: BEÑAT | B37: 1897 | C37: 207 | D37: 6593 | E37: 1656 | F37: 10407 | G37: 3384 | H37: 1796 | I37: 997 | J37: 5629 | K37: 3289 | L37: 6372 | M37: 3468 | N37: =+SUM(B37:M37) -> 45695
A38: ANTONIO | B38: 4392 | C38: 1084 | D38: 6821 | E38: 3651 | F38: 3166 | G38: 15545 | H38: 6333 | I38: 8888 | J38: 9644 | K38: 12461 | L38: 3000 | M38: 3546 | N38: =+SUM(B38:M38) -> 78531
A39: ÁNGEL | B39: 12349 | C39: 2727 | D39: 12173 | E39: 5571 | F39: 2326 | G39: 0 | H39: 0 | I39: 0 | J39: 0 | K39: 0 | L39: 0 | M39: 0 | N39: =+SUM(B39:M39) -> 35146
A40: CORESUR | B40: 3076 | C40: 3373 | D40: 9656 | E40: 5610 | F40: 2732 | G40: 2960 | H40: 5491 | I40: 1341 | J40: 5393 | K40: 4607 | L40: 1817 | M40: 1752 | N40: =+SUM(B40:M40) -> 47808
...

Sheet TRIMESTRAL COMERCIALES
A1: 2022 | B1: 1ER TRIMESTRE | C1: 2DO TRIMESTRE | D1: 3ER TRIMESTRE | E1: 4TO TRIMESTRE
A2: ESPIN | B2: =SUM(Tabla6[[#This Row],[ENERO]:[MARZO]]) -> 216103 | C2: =SUM(Tabla6[[#This Row],[ABRIL]:[JUNIO]]) -> 116834 | D2: =SUM(Tabla6[[#This Row],[JULIO]:[SEPTIEMBRE]]) -> 103537 | E2: =SUM(Tabla6[[#This Row],[OCTUBRE]:[DICIEMBRE]]) -> 96551
A3: LOMBARTE | B3: =SUM(Tabla6[[#This Row],[ENERO]:[MARZO]]) -> 25763 | C3: =SUM(Tabla6[[#This Row],[ABRIL]:[JUNIO]]) -> 16282 | D3: =SUM(Tabla6[[#This Row],[JULIO]:[SEPTIEMBRE]]) -> 15897 | E3: =SUM(Tabla6[[#This Row],[OCTUBRE]:[DICIEMBRE]]) -> 15206
A4: BEÑAT | B4: =SUM(Tabla6[[#This Row],[ENERO]:[MARZO]]) -> 16677 | C4: =SUM(Tabla6[[#This Row],[ABRIL]:[JUNIO]]) -> 11359 | D4: =SUM(Tabla6[[#This Row],[JULIO]:[SEPTIEMBRE]]) -> 14590 | E4: =SUM(Tabla6[[#This Row],[OCTUBRE]:[DICIEMBRE]]) -> 9724
A5: ANTONIO | B5: =SUM(Tabla6[[#This Row],[ENERO]:[MARZO]]) -> 36407 | C5: =SUM(Tabla6[[#This Row],[ABRIL]:[JUNIO]]) -> 39730 | D5: =SUM(Tabla6[[#This Row],[JULIO]:[SEPTIEMBRE]]) -> 31866 | E5: =SUM(Tabla6[[#This Row],[OCTUBRE]:[DICIEMBRE]]) -> 36774
A6: ÁNGEL | B6: =SUM(Tabla6[[#This Row],[ENERO]:[MARZO]]) -> 41689 | C6: =SUM(Tabla6[[#This Row],[ABRIL]:[JUNIO]]) -> 54976 | D6: =SUM(Tabla6[[#This Row],[JULIO]:[SEPTIEMBRE]]) -> 33110 | E6: =SUM(Tabla6[[#This Row],[OCTUBRE]:[DICIEMBRE]]) -> 39506
A7: CORESUR | B7: =SUM(Tabla6[[#This Row],[ENERO]:[MARZO]]) -> 29438 | C7: =SUM(Tabla6[[#This Row],[ABRIL]:[JUNIO]]) -> 26280 | D7: =SUM(Tabla6[[#This Row],[JULIO]:[SEPTIEMBRE]]) -> 15803 | E7: =SUM(Tabla6[[#This Row],[OCTUBRE]:[DICIEMBRE]]) -> 8324
A8: DM | B8: =SUM(Tabla6[[#This Row],[ENERO]:[MARZO]]) -> 74042 | C8: =SUM(Tabla6[[#This Row],[ABRIL]:[JUNIO]]) -> 44420 | D8: =SUM(Tabla6[[#This Row],[JULIO]:[SEPTIEMBRE]]) -> 27118 | E8: =SUM(Tabla6[[#This Row],[OCTUBRE]:[DICIEMBRE]]) -> 34951
A9: ONDIVELA | B9: =SUM(Tabla6[[#This Row],[ENERO]:[MARZO]]) -> 0 | C9: =SUM(Tabla6[[#This Row],[ABRIL]:[JUNIO]]) -> 0 | D9: =SUM(Tabla6[[#This Row],[JULIO]:[SEPTIEMBRE]]) -> 0 | E9: =SUM(Tabla6[[#This Row],[OCTUBRE]:[DICIEMBRE]]) -> 0
A12: 2023 | B12: 1ER TRIMESTRE | C12: 2DO TRIMESTRE | D12: 3ER TRIMESTRE | E12: 4TO TRIMESTRE
A13: ESPIN | B13: =SUM(Tabla6[[#This Row],[ENERO]:[MARZO]]) -> 131594 | C13: =SUM(Tabla6[[#This Row],[ABRIL]:[JUNIO]]) -> 75484 | D13: =SUM(Tabla6[[#This Row],[JULIO]:[SEPTIEMBRE]]) -> 94963 | E13: =SUM(Tabla6[[#This Row],[OCTUBRE]:[DICIEMBRE]]) -> 97383
A14: LOMBARTE | B14: =SUM(Tabla6[[#This Row],[ENERO]:[MARZO]]) -> 21664 | C14: =SUM(Tabla6[[#This Row],[ABRIL]:[JUNIO]]) -> 18967 | D14: =SUM(Tabla6[[#This Row],[JULIO]:[SEPTIEMBRE]]) -> 9796 | E14: =SUM(Tabla6[[#This Row],[OCTUBRE]:[DICIEMBRE]]) -> 20576
A15: BEÑAT | B15: =SUM(Tabla6[[#This Row],[ENERO]:[MARZO]]) -> 18965 | C15: =SUM(Tabla6[[#This Row],[ABRIL]:[JUNIO]]) -> 3211 | D15: =SUM(Tabla6[[#This Row],[JULIO]:[SEPTIEMBRE]]) -> 9837 | E15: =SUM(Tabla6[[#This Row],[OCTUBRE]:[DICIEMBRE]]) -> 27609
A16: ANTONIO | B16: =SUM(Tabla6[[#This Row],[ENERO]:[MARZO]]) -> 36359 | C16: =SUM(Tabla6[[#This Row],[ABRIL]:[JUNIO]]) -> 14207 | D16: =SUM(Tabla6[[#This Row],[JULIO]:[SEPTIEMBRE]]) -> 28772 | E16: =SUM(Tabla6[[#This Row],[OCTUBRE]:[DICIEMBRE]]) -> 25245
A17: ÁNGEL | B17: =SUM(Tabla6[[#This Row],[ENERO]:[MARZO]]) -> 63870 | C17: =SUM(Tabla6[[#This Row],[ABRIL]:[JUNIO]]) -> 30899 | D17: =SUM(Tabla6[[#This Row],[JULIO]:[SEPTIEMBRE]]) -> 40434 | E17: =SUM(Tabla6[[#This Row],[OCTUBRE]:[DICIEMBRE]]) -> 33236
A18: CORESUR | B18: =SUM(Tabla6[[#This Row],[ENERO]:[MARZO]]) -> 20887 | C18: =SUM(Tabla6[[#This Row],[ABRIL]:[JUNIO]]) -> 8775 | D18: =SUM(Tabla6[[#This Row],[JULIO]:[SEPTIEMBRE]]) -> 12627 | E18: =SUM(Tabla6[[#This Row],[OCTUBRE]:[DICIEMBRE]]) -> 14144
A19: DM | B19: =SUM(Tabla6[[#This Row],[ENERO]:[MARZO]]) -> 40906 | C19: =SUM(Tabla6[[#This Row],[ABRIL]:[JUNIO]]) -> 25424 | D19: =SUM(Tabla6[[#This Row],[JULIO]:[SEPTIEMBRE]]) -> 26058 | E19: =SUM(Tabla6[[#This Row],[OCTUBRE]:[DICIEMBRE]]) -> 37594
A20: ONDIVELA | B20: =SUM(Tabla6[[#This Row],[ENERO]:[MARZO]]) -> 0 | C20: =SUM(Tabla6[[#This Row],[ABRIL]:[JUNIO]]) -> 0 | D20: =SUM(Tabla6[[#This Row],[JULIO]:[SEPTIEMBRE]]) -> 0 | E20: =SUM(Tabla6[[#This Row],[OCTUBRE]:[DICIEMBRE]]) -> 0
B22: =+SUM(B12:B19) -> 334245 | C22: =+SUM(C12:C19) -> 176967 | D22: =+SUM(D12:D19) -> 222487 | E22: =+SUM(E12:E19) -> 255787
A23: 2024 | B23: 1ER TRIMESTRE | C23: 2DO TRIMESTRE | D23: 3ER TRIMESTRE | E23: 4TO TRIMESTRE
A24: ESPIN | B24: =SUM(Tabla6[[#This Row],[ENERO]:[MARZO]]) -> 104536 | C24: =SUM(Tabla6[[#This Row],[ABRIL]:[JUNIO]]) -> 90865 | D24: =SUM(Tabla6[[#This Row],[JULIO]:[SEPTIEMBRE]]) -> 111558 | E24: =SUM(Tabla6[[#This Row],[OCTUBRE]:[DICIEMBRE]]) -> 92947
A25: LOMBARTE | B25: =SUM(Tabla6[[#This Row],[ENERO]:[MARZO]]) -> 15890 | C25: =SUM(Tabla6[[#This Row],[ABRIL]:[JUNIO]]) -> 16395 | D25: =SUM(Tabla6[[#This Row],[JULIO]:[SEPTIEMBRE]]) -> 19715 | E25: =SUM(Tabla6[[#This Row],[OCTUBRE]:[DICIEMBRE]]) -> 13606
A26: BEÑAT | B26: =SUM(Tabla6[[#This Row],[ENERO]:[MARZO]]) -> 6247 | C26: =SUM(Tabla6[[#This Row],[ABRIL]:[JUNIO]]) -> 7604 | D26: =SUM(Tabla6[[#This Row],[JULIO]:[SEPTIEMBRE]]) -> 13986 | E26: =SUM(Tabla6[[#This Row],[OCTUBRE]:[DICIEMBRE]]) -> 14092
A27: ANTONIO | B27: =SUM(Tabla6[[#This Row],[ENERO]:[MARZO]]) -> 15257 | C27: =SUM(Tabla6[[#This Row],[ABRIL]:[JUNIO]]) -> 29447 | D27: =SUM(Tabla6[[#This Row],[JULIO]:[SEPTIEMBRE]]) -> 30260 | E27: =SUM(Tabla6[[#This Row],[OCTUBRE]:[DICIEMBRE]]) -> 25411
A28: ÁNGEL | B28: =SUM(Tabla6[[#This Row],[ENERO]:[MARZO]]) -> 36119 | C28: =SUM(Tabla6[[#This Row],[ABRIL]:[JUNIO]]) -> 29707 | D28: =SUM(Tabla6[[#This Row],[JULIO]:[SEPTIEMBRE]]) -> 22093 | E28: =SUM(Tabla6[[#This Row],[OCTUBRE]:[DICIEMBRE]]) -> 35140
A29: CORESUR | B29: =SUM(Tabla6[[#This Row],[ENERO]:[MARZO]]) -> 13803 | C29: =SUM(Tabla6[[#This Row],[ABRIL]:[JUNIO]]) -> 18189 | D29: =SUM(Tabla6[[#This Row],[JULIO]:[SEPTIEMBRE]]) -> 8777 | E29: =SUM(Tabla6[[#This Row],[OCTUBRE]:[DICIEMBRE]]) -> 15320
A30: DM | B30: =SUM(Tabla6[[#This Row],[ENERO]:[MARZO]]) -> 26764 | C30: =SUM(Tabla6[[#This Row],[ABRIL]:[JUNIO]]) -> 34387 | D30: =SUM(Tabla6[[#This Row],[JULIO]:[SEPTIEMBRE]]) -> 33755 | E30: =SUM(Tabla6[[#This Row],[OCTUBRE]:[DICIEMBRE]]) -> 35992
A31: ONDIVELA | B31: =SUM(Tabla6[[#This Row],[ENERO]:[MARZO]]) -> 6424 | C31: =SUM(Tabla6[[#This Row],[ABRIL]:[JUNIO]]) -> 1322 | D31: =SUM(Tabla6[[#This Row],[JULIO]:[SEPTIEMBRE]]) -> 4080 | E31: =SUM(Tabla6[[#This Row],[OCTUBRE]:[DICIEMBRE]]) -> 7009
E32: =+SUM(E24+E25+E26+E27+E28+E29+E30+E31) -> 239517
A34: 2025 | B34: 1ER TRIMESTRE | C34: 2DO TRIMESTRE | D34: 3ER TRIMESTRE | E34: 4TO TRIMESTRE
A35: ESPIN | B35: =SUM(Tabla6[[#This Row],[ENERO]:[MARZO]]) -> 123125 | C35: =SUM(Tabla6[[#This Row],[ABRIL]:[JUNIO]]) -> 83515 | D35: =SUM(Tabla6[[#This Row],[JULIO]:[SEPTIEMBRE]]) -> 111259 | E35: =SUM(Tabla6[[#This Row],[OCTUBRE]:[DICIEMBRE]]) -> 67351
A36: LOMBARTE | B36: =SUM(Tabla6[[#This Row],[ENERO]:[MARZO]]) -> 22900 | C36: =SUM(Tabla6[[#This Row],[ABRIL]:[JUNIO]]) -> 15619 | D36: =SUM(Tabla6[[#This Row],[JULIO]:[SEPTIEMBRE]]) -> 19678 | E36: =SUM(Tabla6[[#This Row],[OCTUBRE]:[DICIEMBRE]]) -> 18429
A37: BEÑAT | B37: =SUM(Tabla6[[#This Row],[ENERO]:[MARZO]]) -> 8697 | C37: =SUM(Tabla6[[#This Row],[ABRIL]:[JUNIO]]) -> 15447 | D37: =SUM(Tabla6[[#This Row],[JULIO]:[SEPTIEMBRE]]) -> 8422 | E37: =SUM(Tabla6[[#This Row],[OCTUBRE]:[DICIEMBRE]]) -> 13129
A38: ANTONIO | B38: =SUM(Tabla6[[#This Row],[ENERO]:[MARZO]]) -> 12297 | C38: =SUM(Tabla6[[#This Row],[ABRIL]:[JUNIO]]) -> 22362 | D38: =SUM(Tabla6[[#This Row],[JULIO]:[SEPTIEMBRE]]) -> 24865 | E38: =SUM(Tabla6[[#This Row],[OCTUBRE]:[DICIEMBRE]]) -> 19007
A39: ÁNGEL | B39: =SUM(Tabla6[[#This Row],[ENERO]:[MARZO]]) -> 27249 | C39: =SUM(Tabla6[[#This Row],[ABRIL]:[JUNIO]]) -> 7897 | D39: =SUM(Tabla6[[#This Row],[JULIO]:[SEPTIEMBRE]]) -> 0 | E39: =SUM(Tabla6[[#This Row],[OCTUBRE]:[DICIEMBRE]]) -> 0
A40: CORESUR | B40: =SUM(Tabla6[[#This Row],[ENERO]:[MARZO]]) -> 16105 | C40: =SUM(Tabla6[[#This Row],[ABRIL]:[JUNIO]]) -> 11302 | D40: =SUM(Tabla6[[#This Row],[JULIO]:[SEPTIEMBRE]]) -> 12225 | E40: =SUM(Tabla6[[#This Row],[OCTUBRE]:[DICIEMBRE]]) -> 8176
A41: DM | B41: =SUM(Tabla6[[#This Row],[ENERO]:[MARZO]]) -> 31104 | C41: =SUM(Tabla6[[#This Row],[ABRIL]:[JUNIO]]) -> 21142 | D41: =SUM(Tabla6[[#This Row],[JULIO]:[SEPTIEMBRE]]) -> 31818 | E41: =SUM(Tabla6[[#This Row],[OCTUBRE]:[DICIEMBRE]]) -> 31996
A42: ONDIVELA | B42: =SUM(Tabla6[[#This Row],[ENERO]:[MARZO]]) -> 356 | C42: =SUM(Tabla6[[#This Row],[ABRIL]:[JUNIO]]) -> 4172 | D42: =SUM(Tabla6[[#This Row],[JULIO]:[SEPTIEMBRE]]) -> 2696 | E42: =SUM(Tabla6[[#This Row],[OCTUBRE]:[DICIEMBRE]]) -> 1961
A44: 2026 | B44: 1ER TRIMESTRE | C44: 2DO TRIMESTRE | D44: 3ER TRIMESTRE | E44: 4TO TRIMESTRE
A45: ESPIN | B45: =+SUM('MENSUAL COMERCIALES'!B49:D49) -> 112544 | C45: =+SUM('MENSUAL COMERCIALES'!C49:E49) -> 90532
...

Sheet ANUAL COMERCIALES
A2: COMERCIAL | B2: 2022 | C2: 2023 | D2: 2024 | E2: 2025 | F2: 2026
A3: ESPIN | B3: 533025 | C3: 399424 | D3: 399906 | E3: =SUM('MENSUAL COMERCIALES'!B35:M35) -> 385250 | F3: =+SUM('MENSUAL COMERCIALES'!B49:M49) -> 269656
A4: LOMBARTE | B4: 73148 | C4: 71003 | D4: 65606 | E4: =SUM('MENSUAL COMERCIALES'!B36:M36) -> 76626 | F4: =+SUM('MENSUAL COMERCIALES'!B50:M50) -> 38977
A5: BEÑAT | B5: 52350 | C5: 59622 | D5: 41929 | E5: =SUM('MENSUAL COMERCIALES'!B37:M37) -> 45695 | F5: =+SUM('MENSUAL COMERCIALES'!B51:M51) -> 35818
A6: ANTONIO | B6: 144777 | C6: 104583 | D6: 100375 | E6: =SUM('MENSUAL COMERCIALES'!B38:M38) -> 78531 | F6: =+SUM('MENSUAL COMERCIALES'!B52:M52) -> 64978
A7: ÁNGEL | B7: 169281 | C7: 168439 | D7: 123059 | E7: =SUM('MENSUAL COMERCIALES'!B39:M39) -> 35146 | F7: =+SUM('MENSUAL COMERCIALES'!B53:M53) -> 50349
A8: CORESUR | B8: 79845 | C8: 56433 | D8: 56089 | E8: =SUM('MENSUAL COMERCIALES'!B40:M40) -> 47808 | F8: =+SUM('MENSUAL COMERCIALES'!B54:M54) -> 129576
A9: DM | B9: 180531 | C9: 129982 | D9: 130898 | E9: =SUM('MENSUAL COMERCIALES'!B41:M41) -> 116060 | F9: =+SUM('MENSUAL COMERCIALES'!B55:M55) -> 11832
A10: ONDIVELA | B10: 0 | C10: 0 | D10: 18835 | E10: =SUM('MENSUAL COMERCIALES'!B42:M42) -> 9185 | F10: =+SUM('MENSUAL COMERCIALES'!B55:M55) -> 11832
A11: MANUEL | B11: =SUM(Tabla6[[#This Row],[ENERO]:[DICIEMBRE]]) -> 0 | E11: =SUM('MENSUAL COMERCIALES'!B43:M43) -> 66012 | F11: =+SUM('MENSUAL COMERCIALES'!B56:M56) -> 76395
F12: =+SUM(Tabla1[2026]) -> 689413

Sheet Hoja1

Sheet ESPIN
A1: MENSUAL | F1: TRIMESTRAL | K1: ANUAL
A2: NUMÉRICO | B2: 2023 | C2: 2024 | D2: 2025 | F2: NUMÉRICO | G2: 2023 | H2: 2024 | I2: 2025 | K2: NUMÉRICO | L2: 2023 | M2: 2024 | N2: 2025
A3: ENERO | B3: ='MENSUAL COMERCIALES'!B13-'MENSUAL COMERCIALES'!B2 -> -2378 | C3: ='MENSUAL COMERCIALES'!B24-'MENSUAL COMERCIALES'!B13 -> -9291 | D3: ='MENSUAL COMERCIALES'!B35-'MENSUAL COMERCIALES'!B24 -> 15554 | F3: 1ER TRIMESTRE | G3: ='TRIMESTRAL COMERCIALES'!B13-'TRIMESTRAL COMERCIALES'!B2 -> -84509 | H3: ='TRIMESTRAL COMERCIALES'!B24-'TRIMESTRAL COMERCIALES'!B13 -> -27058 | I3: =+'TRIMESTRAL COMERCIALES'!B35-'TRIMESTRAL COMERCIALES'!B24 -> 18589 | K3: ANUAL | L3: =Tabla1[[#This Row],[2023]]-Tabla1[[#This Row],[2022]] -> -133601 | M3: =Tabla1[[#This Row],[2024]]-Tabla1[[#This Row],[2023]] -> 482 | N3: =Tabla1[[#This Row],[2025]]-Tabla1[[#This Row],[2024]] -> -14656
A4: FEBRERO | B4: ='MENSUAL COMERCIALES'!C13-'MENSUAL COMERCIALES'!C2 -> -83008 | C4: ='MENSUAL COMERCIALES'!C24-'MENSUAL COMERCIALES'!C13 -> 12108 | D4: ='MENSUAL COMERCIALES'!C35-'MENSUAL COMERCIALES'!C24 -> -18577 | F4: 2DO TRIMESTRE | G4: ='TRIMESTRAL COMERCIALES'!C13-'TRIMESTRAL COMERCIALES'!C2 -> -41350 | H4: ='TRIMESTRAL COMERCIALES'!E24-'TRIMESTRAL COMERCIALES'!E13 -> -4436 | I4: =+'TRIMESTRAL COMERCIALES'!C35-'TRIMESTRAL COMERCIALES'!C24 -> -7350
A5: MARZO | B5: ='MENSUAL COMERCIALES'!D13-'MENSUAL COMERCIALES'!D2 -> 877 | C5: ='MENSUAL COMERCIALES'!D24-'MENSUAL COMERCIALES'!D13 -> -29875 | D5: ='MENSUAL COMERCIALES'!D35-'MENSUAL COMERCIALES'!D24 -> 21612 | F5: 3ER TRIMESTRE | G5: ='TRIMESTRAL COMERCIALES'!D13-'TRIMESTRAL COMERCIALES'!D2 -> -8574 | H5: ='TRIMESTRAL COMERCIALES'!D24-'TRIMESTRAL COMERCIALES'!D13 -> 16595 | I5: =+'TRIMESTRAL COMERCIALES'!D35-'TRIMESTRAL COMERCIALES'!D24 -> -299
A6: ABRIL | B6: ='MENSUAL COMERCIALES'!E13-'MENSUAL COMERCIALES'!E2 -> -27208 | C6: ='MENSUAL COMERCIALES'!E24-'MENSUAL COMERCIALES'!E13 -> 31082 | D6: ='MENSUAL COMERCIALES'!E35-'MENSUAL COMERCIALES'!E24 -> -25715 | F6: 4TO TRIMESTRE | G6: ='TRIMESTRAL COMERCIALES'!E13-'TRIMESTRAL COMERCIALES'!E2 -> 832 | H6: ='TRIMESTRAL COMERCIALES'!E24-'TRIMESTRAL COMERCIALES'!E13 -> -4436 | I6: =+'TRIMESTRAL COMERCIALES'!B38-'TRIMESTRAL COMERCIALES'!B27 -> -2960
A7: MAYO | B7: ='MENSUAL COMERCIALES'!F13-'MENSUAL COMERCIALES'!F2 -> 12592 | C7: ='MENSUAL COMERCIALES'!F24-'MENSUAL COMERCIALES'!F13 -> -16298 | D7: ='MENSUAL COMERCIALES'!F35-'MENSUAL COMERCIALES'!F24 -> -10494
A8: JUNIO | B8: ='MENSUAL COMERCIALES'!G13-'MENSUAL COMERCIALES'!G2 -> -26734 | C8: ='MENSUAL COMERCIALES'!G24-'MENSUAL COMERCIALES'!G13 -> 597 | D8: ='MENSUAL COMERCIALES'!G35-'MENSUAL COMERCIALES'!G24 -> 28859
A9: JULIO | B9: ='MENSUAL COMERCIALES'!H13-'MENSUAL COMERCIALES'!H2 -> -19163 | C9: ='MENSUAL COMERCIALES'!H24-'MENSUAL COMERCIALES'!H13 -> -13610 | D9: ='MENSUAL COMERCIALES'!H35-'MENSUAL COMERCIALES'!H24 -> 14361
A10: AGOSTO | B10: ='MENSUAL COMERCIALES'!I13-'MENSUAL COMERCIALES'!I2 -> -10931 | C10: ='MENSUAL COMERCIALES'!I24-'MENSUAL COMERCIALES'!I13 -> 48721 | D10: ='MENSUAL COMERCIALES'!I35-'MENSUAL COMERCIALES'!I24 -> -35992
A11: SEPTIEMBRE | B11: ='MENSUAL COMERCIALES'!J13-'MENSUAL COMERCIALES'!J2 -> 21520 | C11: ='MENSUAL COMERCIALES'!J24-'MENSUAL COMERCIALES'!J13 -> -18516 | D11: ='MENSUAL COMERCIALES'!J35-'MENSUAL COMERCIALES'!J24 -> 21332
A12: OCTUBRE | B12: ='MENSUAL COMERCIALES'!K13-'MENSUAL COMERCIALES'!K2 -> 1566 | C12: ='MENSUAL COMERCIALES'!K24-'MENSUAL COMERCIALES'!K13 -> -1070 | D12: ='MENSUAL COMERCIALES'!K35-'MENSUAL COMERCIALES'!K24 -> -15241
A13: NOVIEMBRE | B13: =Tabla6[[#This Row],[NOVIEMBRE]]-'MENSUAL COMERCIALES'!L2 -> 1218 | C13: ='MENSUAL COMERCIALES'!L24-Tabla6[[#This Row],[NOVIEMBRE]] -> -9905 | D13: ='MENSUAL COMERCIALES'!L35-'MENSUAL COMERCIALES'!L24 -> -6941
A14: DICIEMBRE | B14: ='MENSUAL COMERCIALES'!M13-'MENSUAL COMERCIALES'!M2 -> -1952 | C14: ='MENSUAL COMERCIALES'!M24-'MENSUAL COMERCIALES'!M13 -> 6539 | D14: ='MENSUAL COMERCIALES'!M35-'MENSUAL COMERCIALES'!M24 -> -3414
A17: MENSUAL | F17: TRIMESTRAL | K17: ANUAL
A18: % | B18: 2023 | C18: 2024 | D18: 2025 | F18: % | G18: 2023 | H18: 2024 | I18: 2025 | K18: % | L18: 2023 | M18: 2024 | N18: 2025
A19: ENERO | B19: =('MENSUAL COMERCIALES'!B13-'MENSUAL COMERCIALES'!B2)/'MENSUAL COMERCIALES'!B2 -> -0.046436243 | C19: =('MENSUAL COMERCIALES'!B24-'MENSUAL COMERCIALES'!B13)/'MENSUAL COMERCIALES'!B13 -> -0.19026458 | D19: =('MENSUAL COMERCIALES'!B35-'MENSUAL COMERCIALES'!B24)/'MENSUAL COMERCIALES'!B24 -> 0.39336385 | F19: 1ER TRIMESTRE | G19: =('TRIMESTRAL COMERCIALES'!B13-'TRIMESTRAL COMERCIALES'!B2)/'TRIMESTRAL COMERCIALES'!B2 -> -0.39105889 | H19: =('TRIMESTRAL COMERCIALES'!B24-'TRIMESTRAL COMERCIALES'!B13)/'TRIMESTRAL COMERCIALES'!B13 -> -0.20561728 | I19: =('TRIMESTRAL COMERCIALES'!B35-'TRIMESTRAL COMERCIALES'!B24)/'TRIMESTRAL COMERCIALES'!B24 -> 0.17782391 | L19: =('ANUAL COMERCIALES'!C3-'ANUAL COMERCIALES'!B3)/'ANUAL COMERCIALES'!B3 -> -0.25064678 | M19: =('ANUAL COMERCIALES'!D3-'ANUAL COMERCIALES'!C3)/'ANUAL COMERCIALES'!C3 -> 0.0012067377 | N19: =('ANUAL COMERCIALES'!E3-'ANUAL COMERCIALES'!D3)/'ANUAL COMERCIALES'!D3 -> -0.036648612
A20: FEBRERO | B20: =('MENSUAL COMERCIALES'!C13-'MENSUAL COMERCIALES'!C2)/'MENSUAL COMERCIALES'!C2 -> -0.77203099 | C20: =('MENSUAL COMERCIALES'!C24-'MENSUAL COMERCIALES'!C13)/'MENSUAL COMERCIALES'!C13 -> 0.49398229 | D20: =('MENSUAL COMERCIALES'!C35-'MENSUAL COMERCIALES'!C24)/'MENSUAL COMERCIALES'!C24 -> -0.50730495 | F20: 2DO TRIMESTRE | G20: =('TRIMESTRAL COMERCIALES'!C13-'TRIMESTRAL COMERCIALES'!C2)/'TRIMESTRAL COMERCIALES'!C2 -> -0.35392095 | H20: =('TRIMESTRAL COMERCIALES'!C24-'TRIMESTRAL COMERCIALES'!C13)/'TRIMESTRAL COMERCIALES'!C13 -> 0.20376504 | I20: =('TRIMESTRAL COMERCIALES'!C35-'TRIMESTRAL COMERCIALES'!C24)/'TRIMESTRAL COMERCIALES'!C24 -> -0.080889231
A21: MARZO | B21: =('MENSUAL COMERCIALES'!D13-'MENSUAL COMERCIALES'!D2)/'MENSUAL COMERCIALES'!D2 -> 0.015285669 | C21: =('MENSUAL COMERCIALES'!D24-'MENSUAL COMERCIALES'!D13)/'MENSUAL COMERCIALES'!D13 -> -0.51286673 | D21: =('MENSUAL COMERCIALES'!D35-'MENSUAL COMERCIALES'!D24)/'MENSUAL COMERCIALES'!D24 -> 0.76162955 | F21: 3ER TRIMESTRE | G21: =('TRIMESTRAL COMERCIALES'!D13-'TRIMESTRAL COMERCIALES'!D2)/'TRIMESTRAL COMERCIALES'!D2 -> -0.082810976 | H21: =('TRIMESTRAL COMERCIALES'!D24-'TRIMESTRAL COMERCIALES'!D13)/'TRIMESTRAL COMERCIALES'!D13 -> 0.17475227 | I21: =('TRIMESTRAL COMERCIALES'!D35-'TRIMESTRAL COMERCIALES'!D24)/'TRIMESTRAL COMERCIALES'!D24 -> -0.0026802202
A22: ABRIL | B22: =('MENSUAL COMERCIALES'!E13-'MENSUAL COMERCIALES'!E2)/'MENSUAL COMERCIALES'!E2 -> -0.62023845 | C22: =('MENSUAL COMERCIALES'!E24-'MENSUAL COMERCIALES'!E13)/'MENSUAL COMERCIALES'!E13 -> 1.8657783 | D22: =('MENSUAL COMERCIALES'!E24-'MENSUAL COMERCIALES'!E13)/'MENSUAL COMERCIALES'!E13 -> 1.8657783 | F22: 4TO TRIMESTRE | G22: =('TRIMESTRAL COMERCIALES'!E13-'TRIMESTRAL COMERCIALES'!E2)/'TRIMESTRAL COMERCIALES'!E2 -> 0.0086172075 | H22: =('TRIMESTRAL COMERCIALES'!E24-'TRIMESTRAL COMERCIALES'!E13)/'TRIMESTRAL COMERCIALES'!E13 -> -0.045552098 | I22: =('TRIMESTRAL COMERCIALES'!E35-'TRIMESTRAL COMERCIALES'!E24)/'TRIMESTRAL COMERCIALES'!E24 -> -0.27538275
A23: MAYO | B23: =('MENSUAL COMERCIALES'!F13-'MENSUAL COMERCIALES'!F2)/'MENSUAL COMERCIALES'!F2 -> 0.42108079 | C23: =('MENSUAL COMERCIALES'!F24-'MENSUAL COMERCIALES'!F13)/'MENSUAL COMERCIALES'!F13 -> -0.38351845 | D23: =('MENSUAL COMERCIALES'!F35-'MENSUAL COMERCIALES'!F24)/'MENSUAL COMERCIALES'!F24 -> -0.40056493
A24: JUNIO | B24: =('MENSUAL COMERCIALES'!G13-'MENSUAL COMERCIALES'!G2)/'MENSUAL COMERCIALES'!G2 -> -0.62081137 | C24: =(Tabla6[[#This Row],[JUNIO]]-'MENSUAL COMERCIALES'!G13)/'MENSUAL COMERCIALES'!G13 -> 0.03656072 | D24: =('MENSUAL COMERCIALES'!G35-Tabla6[[#This Row],[JUNIO]])/Tabla6[[#This Row],[JUNIO]] -> 1.70501
A25: JULIO | B25: =('MENSUAL COMERCIALES'!H13-'MENSUAL COMERCIALES'!H2)/'MENSUAL COMERCIALES'!H2 -> -0.35495582 | C25: =('MENSUAL COMERCIALES'!H24-'MENSUAL COMERCIALES'!H13)/'MENSUAL COMERCIALES'!H13 -> -0.39082242 | D25: =('MENSUAL COMERCIALES'!H35-'MENSUAL COMERCIALES'!H24)/'MENSUAL COMERCIALES'!H24 -> 0.67695861
A26: AGOSTO | B26: =('MENSUAL COMERCIALES'!I13-'MENSUAL COMERCIALES'!I2)/'MENSUAL COMERCIALES'!I2 -> -0.45580018 | C26: =('MENSUAL COMERCIALES'!I24-'MENSUAL COMERCIALES'!I13)/'MENSUAL COMERCIALES'!I13 -> 3.7331239 | D26: =('MENSUAL COMERCIALES'!I35-'MENSUAL COMERCIALES'!I24)/'MENSUAL COMERCIALES'!I24 -> -0.58265881
A27: SEPTIEMBRE | B27: =('MENSUAL COMERCIALES'!J13-'MENSUAL COMERCIALES'!J2)/'MENSUAL COMERCIALES'!J2 -> 0.8416771 | C27: =('MENSUAL COMERCIALES'!J24-'MENSUAL COMERCIALES'!J13)/'MENSUAL COMERCIALES'!J13 -> -0.3932212 | D27: =('MENSUAL COMERCIALES'!J35-'MENSUAL COMERCIALES'!J24)/'MENSUAL COMERCIALES'!J24 -> 0.74660507
A28: OCTUBRE | B28: =('MENSUAL COMERCIALES'!K13-'MENSUAL COMERCIALES'!K2)/'MENSUAL COMERCIALES'!K2 -> 0.03952649 | C28: =('MENSUAL COMERCIALES'!K24-'MENSUAL COMERCIALES'!K13)/'MENSUAL COMERCIALES'!K13 -> -0.025980333 | D28: =('MENSUAL COMERCIALES'!K35-'MENSUAL COMERCIALES'!K24)/'MENSUAL COMERCIALES'!K24 -> -0.37993269
A29: NOVIEMBRE | B29: =('MENSUAL COMERCIALES'!L13-'MENSUAL COMERCIALES'!L2)/'MENSUAL COMERCIALES'!L2 -> 0.035214525 | C29: =('MENSUAL COMERCIALES'!L24-'MENSUAL COMERCIALES'!L13)/'MENSUAL COMERCIALES'!L13 -> -0.27662962 | D29: =('MENSUAL COMERCIALES'!L35-'MENSUAL COMERCIALES'!L24)/'MENSUAL COMERCIALES'!L24 -> -0.26798193
A30: DICIEMBRE | B30: =('MENSUAL COMERCIALES'!M13-'MENSUAL COMERCIALES'!M2)/'MENSUAL COMERCIALES'!M2 -> -0.08736126 | C30: =('MENSUAL COMERCIALES'!M24-'MENSUAL COMERCIALES'!M13)/'MENSUAL COMERCIALES'!M13 -> 0.32066497 | D30: =('MENSUAL COMERCIALES'!M35-'MENSUAL COMERCIALES'!M24)/'MENSUAL COMERCIALES'!M24 -> -0.12676841

Sheet LOMBARTE
A1: MENSUAL | F1: TRIMESTRAL | K1: ANUAL
A2: NUMÉRICO | B2: 2023 | C2: 2024 | D2: 2025 | F2: NUMÉRICO | G2: 2023 | H2: 2024 | I2: 2025 | K2: NUMÉRICO | L2: 2023 | M2: 2024 | N2: 2025
A3: ENERO | B3: ='MENSUAL COMERCIALES'!B14-'MENSUAL COMERCIALES'!B3 -> 1319 | C3: ='MENSUAL COMERCIALES'!B25-'MENSUAL COMERCIALES'!B14 -> 4596 | D3: ='MENSUAL COMERCIALES'!B36-'MENSUAL COMERCIALES'!B25 -> -1831 | F3: 1ER TRIMESTRE | G3: ='TRIMESTRAL COMERCIALES'!B14-'TRIMESTRAL COMERCIALES'!B3 -> -4099 | H3: ='TRIMESTRAL COMERCIALES'!B25-'TRIMESTRAL COMERCIALES'!B14 -> -5774 | I3: ='TRIMESTRAL COMERCIALES'!B36-'TRIMESTRAL COMERCIALES'!B25 -> 7010 | K3: ANUAL | L3: ='ANUAL COMERCIALES'!C4-'ANUAL COMERCIALES'!B4 -> -2145 | M3: ='ANUAL COMERCIALES'!D4-'ANUAL COMERCIALES'!C4 -> -5397 | N3: ='ANUAL COMERCIALES'!E4-'ANUAL COMERCIALES'!D4 -> 11020
A4: FEBRERO | B4: ='MENSUAL COMERCIALES'!C14-'MENSUAL COMERCIALES'!C3 -> -11623 | C4: ='MENSUAL COMERCIALES'!C25-'MENSUAL COMERCIALES'!C14 -> 2112 | D4: ='MENSUAL COMERCIALES'!C36-'MENSUAL COMERCIALES'!C25 -> 1341 | F4: 2DO TRIMESTRE | G4: ='TRIMESTRAL COMERCIALES'!C14-'TRIMESTRAL COMERCIALES'!C3 -> 2685 | H4: ='TRIMESTRAL COMERCIALES'!C25-'TRIMESTRAL COMERCIALES'!C14 -> -2572 | I4: ='TRIMESTRAL COMERCIALES'!C36-'TRIMESTRAL COMERCIALES'!C25 -> -776
A5: MARZO | B5: ='MENSUAL COMERCIALES'!D14-'MENSUAL COMERCIALES'!D3 -> 6205 | C5: ='MENSUAL COMERCIALES'!D25-'MENSUAL COMERCIALES'!D14 -> -12482 | D5: ='MENSUAL COMERCIALES'!D36-'MENSUAL COMERCIALES'!D25 -> 7500 | F5: 3ER TRIMESTRE | G5: ='TRIMESTRAL COMERCIALES'!D14-'TRIMESTRAL COMERCIALES'!D3 -> -6101 | H5: ='TRIMESTRAL COMERCIALES'!D25-'TRIMESTRAL COMERCIALES'!D14 -> 9919 | I5: ='TRIMESTRAL COMERCIALES'!D36-'TRIMESTRAL COMERCIALES'!D25 -> -37
A6: ABRIL | B6: ='MENSUAL COMERCIALES'!E14-'MENSUAL COMERCIALES'!E3 -> -6285 | C6: ='MENSUAL COMERCIALES'!E25-'MENSUAL COMERCIALES'!E14 -> 7871 | D6: ='MENSUAL COMERCIALES'!E36-'MENSUAL COMERCIALES'!E25 -> -3751 | F6: 4TO TRIMESTRE | G6: ='TRIMESTRAL COMERCIALES'!E14-'TRIMESTRAL COMERCIALES'!E3 -> 5370 | H6: ='TRIMESTRAL COMERCIALES'!E25-'TRIMESTRAL COMERCIALES'!E14 -> -6970 | I6: ='TRIMESTRAL COMERCIALES'!E36-'TRIMESTRAL COMERCIALES'!E25 -> 4823
A7: MAYO | B7: ='MENSUAL COMERCIALES'!F14-'MENSUAL COMERCIALES'!F3 -> 588 | C7: ='MENSUAL COMERCIALES'!F25-'MENSUAL COMERCIALES'!F14 -> 311 | D7: ='MENSUAL COMERCIALES'!F36-'MENSUAL COMERCIALES'!F25 -> -3140
A8: JUNIO | B8: ='MENSUAL COMERCIALES'!G14-'MENSUAL COMERCIALES'!G3 -> 8382 | C8: ='MENSUAL COMERCIALES'!G25-'MENSUAL COMERCIALES'!G14 -> -10754 | D8: ='MENSUAL COMERCIALES'!G36-'MENSUAL COMERCIALES'!G25 -> 6115
A9: JULIO | B9: ='MENSUAL COMERCIALES'!H14-'MENSUAL COMERCIALES'!H3 -> -6107 | C9: ='MENSUAL COMERCIALES'!H25-'MENSUAL COMERCIALES'!H14 -> 3560 | D9: ='MENSUAL COMERCIALES'!H36-'MENSUAL COMERCIALES'!H25 -> -1813
A10: AGOSTO | B10: ='MENSUAL COMERCIALES'!I14-'MENSUAL COMERCIALES'!I3 -> 505 | C10: ='MENSUAL COMERCIALES'!I25-'MENSUAL COMERCIALES'!I14 -> 3465 | D10: ='MENSUAL COMERCIALES'!I36-'MENSUAL COMERCIALES'!I25 -> -43
A11: SEPTIEMBRE | B11: ='MENSUAL COMERCIALES'!J14-'MENSUAL COMERCIALES'!J3 -> -499 | C11: ='MENSUAL COMERCIALES'!J25-'MENSUAL COMERCIALES'!J14 -> 2894 | D11: ='MENSUAL COMERCIALES'!J36-'MENSUAL COMERCIALES'!J25 -> 1819
A12: OCTUBRE | B12: ='MENSUAL COMERCIALES'!K14-'MENSUAL COMERCIALES'!K3 -> -1214 | C12: ='MENSUAL COMERCIALES'!K25-'MENSUAL COMERCIALES'!K14 -> -2044 | D12: ='MENSUAL COMERCIALES'!K36-'MENSUAL COMERCIALES'!K25 -> 3491
A13: NOVIEMBRE | B13: ='MENSUAL COMERCIALES'!L14-'MENSUAL COMERCIALES'!L3 -> 1856 | C13: ='MENSUAL COMERCIALES'!L25-'MENSUAL COMERCIALES'!L14 -> -471 | D13: ='MENSUAL COMERCIALES'!L36-'MENSUAL COMERCIALES'!L25 -> 299
A14: DICIEMBRE | B14: ='MENSUAL COMERCIALES'!M14-'MENSUAL COMERCIALES'!M3 -> 4728 | C14: ='MENSUAL COMERCIALES'!M25-'MENSUAL COMERCIALES'!M14 -> -4455 | D14: ='MENSUAL COMERCIALES'!M36-'MENSUAL COMERCIALES'!M25 -> 1033
A17: MENSUAL | F17: TRIMESTRAL | K17: ANUAL
A18: % | B18: 2023 | C18: 2024 | D18: 2025 | F18: % | G18: 2023 | H18: 2024 | I18: 2025 | K18: % | L18: 2023 | M18: 2024 | N18: 2025
A19: ENERO | B19: =('MENSUAL COMERCIALES'!B14-'MENSUAL COMERCIALES'!B3)/'MENSUAL COMERCIALES'!B3 -> 0.58989267 | C19: =('MENSUAL COMERCIALES'!B25-'MENSUAL COMERCIALES'!B14)/'MENSUAL COMERCIALES'!B14 -> 1.292827 | D19: =('MENSUAL COMERCIALES'!B36-'MENSUAL COMERCIALES'!B25)/'MENSUAL COMERCIALES'!B25 -> -0.22463501 | F19: 1ER TRIMESTRE | G19: =('TRIMESTRAL COMERCIALES'!B14-'TRIMESTRAL COMERCIALES'!B3)/'TRIMESTRAL COMERCIALES'!B3 -> -0.15910414 | H19: =('TRIMESTRAL COMERCIALES'!B25-'TRIMESTRAL COMERCIALES'!B14)/'TRIMESTRAL COMERCIALES'!B14 -> -0.26652511 | I19: =('TRIMESTRAL COMERCIALES'!B36-'TRIMESTRAL COMERCIALES'!B25)/'TRIMESTRAL COMERCIALES'!B25 -> 0.44115796 | L19: =('ANUAL COMERCIALES'!C4-'ANUAL COMERCIALES'!B4)/'ANUAL COMERCIALES'!B4 -> -0.02932411 | M19: =('ANUAL COMERCIALES'!D4-'ANUAL COMERCIALES'!C4)/'ANUAL COMERCIALES'!C4 -> -0.076010873 | N19: =('ANUAL COMERCIALES'!E4-'ANUAL COMERCIALES'!D4)/'ANUAL COMERCIALES'!D4 -> 0.16797244
A20: FEBRERO | B20: =('MENSUAL COMERCIALES'!C14-'MENSUAL COMERCIALES'!C3)/'MENSUAL COMERCIALES'!C3 -> -0.81759989 | C20: =('MENSUAL COMERCIALES'!C25-'MENSUAL COMERCIALES'!C14)/'MENSUAL COMERCIALES'!C14 -> 0.81450058 | D20: =('MENSUAL COMERCIALES'!C36-'MENSUAL COMERCIALES'!C25)/'MENSUAL COMERCIALES'!C25 -> 0.28501594 | F20: 2DO TRIMESTRE | G20: =('TRIMESTRAL COMERCIALES'!C14-'TRIMESTRAL COMERCIALES'!C3)/'TRIMESTRAL COMERCIALES'!C3 -> 0.16490603 | H20: =('TRIMESTRAL COMERCIALES'!C25-'TRIMESTRAL COMERCIALES'!C14)/'TRIMESTRAL COMERCIALES'!C14 -> -0.13560394 | I20: =('TRIMESTRAL COMERCIALES'!C36-'TRIMESTRAL COMERCIALES'!C25)/'TRIMESTRAL COMERCIALES'!C25 -> -0.047331504
A21: MARZO | B21: =('MENSUAL COMERCIALES'!D14-'MENSUAL COMERCIALES'!D3)/'MENSUAL COMERCIALES'!D3 -> 0.66641607 | C21: =('MENSUAL COMERCIALES'!D25-'MENSUAL COMERCIALES'!D14)/'MENSUAL COMERCIALES'!D14 -> -0.80445991 | D21: =('MENSUAL COMERCIALES'!D36-'MENSUAL COMERCIALES'!D25)/'MENSUAL COMERCIALES'!D25 -> 2.4719842 | F21: 3ER TRIMESTRE | G21: =('TRIMESTRAL COMERCIALES'!D14-'TRIMESTRAL COMERCIALES'!D3)/'TRIMESTRAL COMERCIALES'!D3 -> -0.3837831 | H21: =('TRIMESTRAL COMERCIALES'!D25-'TRIMESTRAL COMERCIALES'!D14)/'TRIMESTRAL COMERCIALES'!D14 -> 1.0125561 | I21: =('TRIMESTRAL COMERCIALES'!D36-'TRIMESTRAL COMERCIALES'!D25)/'TRIMESTRAL COMERCIALES'!D25 -> -0.0018767436
A22: ABRIL | B22: =('MENSUAL COMERCIALES'!E14-'MENSUAL COMERCIALES'!E3)/'MENSUAL COMERCIALES'!E3 -> -0.85778627 | C22: =('MENSUAL COMERCIALES'!E25-'MENSUAL COMERCIALES'!E14)/'MENSUAL COMERCIALES'!E14 -> 7.5537428 | D22: =('MENSUAL COMERCIALES'!E36-'MENSUAL COMERCIALES'!E25)/'MENSUAL COMERCIALES'!E25 -> -0.42084596 | F22: 4TO TRIMESTRE | G22: =('TRIMESTRAL COMERCIALES'!E14-'TRIMESTRAL COMERCIALES'!E3)/'TRIMESTRAL COMERCIALES'!E3 -> 0.35315007 | H22: =('TRIMESTRAL COMERCIALES'!E25-'TRIMESTRAL COMERCIALES'!E14)/'TRIMESTRAL COMERCIALES'!E14 -> -0.33874417 | I22: =('TRIMESTRAL COMERCIALES'!E36-'TRIMESTRAL COMERCIALES'!E25)/'TRIMESTRAL COMERCIALES'!E25 -> 0.35447597
A23: MAYO | B23: =('MENSUAL COMERCIALES'!F14-'MENSUAL COMERCIALES'!F3)/'MENSUAL COMERCIALES'!F3 -> 0.11318576 | C23: =('MENSUAL COMERCIALES'!F25-'MENSUAL COMERCIALES'!F14)/'MENSUAL COMERCIALES'!F14 -> 0.053778316 | D23: =('MENSUAL COMERCIALES'!F36-'MENSUAL COMERCIALES'!F25)/'MENSUAL COMERCIALES'!F25 -> -0.51526091
A24: JUNIO | B24: =('MENSUAL COMERCIALES'!G14-'MENSUAL COMERCIALES'!G3)/'MENSUAL COMERCIALES'!G3 -> 2.2292553 | C24: =('MENSUAL COMERCIALES'!G25-'MENSUAL COMERCIALES'!G14)/'MENSUAL COMERCIALES'!G14 -> -0.88568605 | D24: =('MENSUAL COMERCIALES'!G36-'MENSUAL COMERCIALES'!G25)/'MENSUAL COMERCIALES'!G25 -> 4.4056196
A25: JULIO | B25: =('MENSUAL COMERCIALES'!H14-'MENSUAL COMERCIALES'!H3)/'MENSUAL COMERCIALES'!H3 -> -0.67346714 | C25: =('MENSUAL COMERCIALES'!H25-'MENSUAL COMERCIALES'!H14)/'MENSUAL COMERCIALES'!H14 -> 1.2022965 | D25: =('MENSUAL COMERCIALES'!H36-Tabla6[[#This Row],[JULIO]])/Tabla6[[#This Row],[JULIO]] -> -0.27802484
A26: AGOSTO | B26: =('MENSUAL COMERCIALES'!I14-'MENSUAL COMERCIALES'!I3)/'MENSUAL COMERCIALES'!I3 -> 0.26904635 | C26: =('MENSUAL COMERCIALES'!I25-'MENSUAL COMERCIALES'!I14)/'MENSUAL COMERCIALES'!I14 -> 1.4546599 | D26: =('MENSUAL COMERCIALES'!I36-'MENSUAL COMERCIALES'!I25)/'MENSUAL COMERCIALES'!I25 -> -0.0073541987
A27: SEPTIEMBRE | B27: =('MENSUAL COMERCIALES'!J14-'MENSUAL COMERCIALES'!J3)/'MENSUAL COMERCIALES'!J3 -> -0.10076737 | C27: =('MENSUAL COMERCIALES'!J25-'MENSUAL COMERCIALES'!J14)/'MENSUAL COMERCIALES'!J14 -> 0.64989894 | D27: =('MENSUAL COMERCIALES'!J36-'MENSUAL COMERCIALES'!J25)/'MENSUAL COMERCIALES'!J25 -> 0.24758405
A28: OCTUBRE | B28: =('MENSUAL COMERCIALES'!K14-'MENSUAL COMERCIALES'!K3)/'MENSUAL COMERCIALES'!K3 -> -0.17599304 | C28: =('MENSUAL COMERCIALES'!K25-'MENSUAL COMERCIALES'!K14)/'MENSUAL COMERCIALES'!K14 -> -0.35960591 | D28: =('MENSUAL COMERCIALES'!K36-'MENSUAL COMERCIALES'!K25)/'MENSUAL COMERCIALES'!K25 -> 0.95906593
A29: NOVIEMBRE | B29: =('MENSUAL COMERCIALES'!L14-'MENSUAL COMERCIALES'!L3)/'MENSUAL COMERCIALES'!L3 -> 0.36774321 | C29: =('MENSUAL COMERCIALES'!L25-'MENSUAL COMERCIALES'!L14)/'MENSUAL COMERCIALES'!L14 -> -0.068231204 | D29: =('MENSUAL COMERCIALES'!L36-'MENSUAL COMERCIALES'!L25)/'MENSUAL COMERCIALES'!L25 -> 0.046486318
A30: DICIEMBRE | B30: =('MENSUAL COMERCIALES'!M14-'MENSUAL COMERCIALES'!M3)/'MENSUAL COMERCIALES'!M3 -> 1.449862 | C30: =('MENSUAL COMERCIALES'!M25-'MENSUAL COMERCIALES'!M14)/'MENSUAL COMERCIALES'!M14 -> -0.55764176 | D30: =('MENSUAL COMERCIALES'!M36-'MENSUAL COMERCIALES'!M25)/'MENSUAL COMERCIALES'!M25 -> 0.29230334

Sheet BEÑAT
A1: MENSUAL | F1: TRIMESTRAL | K1: ANUAL
A2: NUMÉRICO | B2: 2023 | C2: 2024 | D2: 2025 | F2: NUMÉRICO | G2: 2023 | H2: 2024 | I2: 2025 | K2: NUMÉRICO | L2: 2023 | M2: 2024 | N2: 2025
A3: ENERO | B3: ='MENSUAL COMERCIALES'!B15-'MENSUAL COMERCIALES'!B4 -> 7602 | C3: ='MENSUAL COMERCIALES'!B26-'MENSUAL COMERCIALES'!B15 -> -7353 | D3: ='MENSUAL COMERCIALES'!B37-'MENSUAL COMERCIALES'!B26 -> 1648 | F3: 1ER TRIMESTRE | G3: ='TRIMESTRAL COMERCIALES'!B15-'TRIMESTRAL COMERCIALES'!B4 -> 2288 | H3: ='TRIMESTRAL COMERCIALES'!B26-'TRIMESTRAL COMERCIALES'!B15 -> -12718 | I3: ='TRIMESTRAL COMERCIALES'!B37-'TRIMESTRAL COMERCIALES'!B26 -> 2450 | L3: ='ANUAL COMERCIALES'!C5-'ANUAL COMERCIALES'!B5 -> 7272 | M3: ='ANUAL COMERCIALES'!D5-'ANUAL COMERCIALES'!C5 -> -17693 | N3: ='ANUAL COMERCIALES'!E5-'ANUAL COMERCIALES'!D5 -> 3766
A4: FEBRERO | B4: ='MENSUAL COMERCIALES'!C15-Tabla6[[#This Row],[FEBRERO]] -> -1529 | C4: ='MENSUAL COMERCIALES'!C26-'MENSUAL COMERCIALES'!C15 -> 5035 | D4: ='MENSUAL COMERCIALES'!C37-'MENSUAL COMERCIALES'!C26 -> -5791 | F4: 2DO TRIMESTRE | G4: ='TRIMESTRAL COMERCIALES'!C15-Tabla2[[#This Row],[2DO TRIMESTRE]] -> -8148 | H4: ='TRIMESTRAL COMERCIALES'!C26-'TRIMESTRAL COMERCIALES'!C15 -> 4393 | I4: ='TRIMESTRAL COMERCIALES'!C37-'TRIMESTRAL COMERCIALES'!C26 -> 7843
A5: MARZO | B5: ='MENSUAL COMERCIALES'!D15-'MENSUAL COMERCIALES'!D4 -> -3785 | C5: ='MENSUAL COMERCIALES'!D26-'MENSUAL COMERCIALES'!D15 -> -10400 | D5: ='MENSUAL COMERCIALES'!D37-'MENSUAL COMERCIALES'!D26 -> 6593 | F5: 3ER TRIMESTRE | G5: ='TRIMESTRAL COMERCIALES'!D15-'TRIMESTRAL COMERCIALES'!D4 -> -4753 | H5: ='TRIMESTRAL COMERCIALES'!D26-'TRIMESTRAL COMERCIALES'!D15 -> 4149 | I5: ='TRIMESTRAL COMERCIALES'!D37-'TRIMESTRAL COMERCIALES'!D26 -> -5564
A6: ABRIL | B6: ='MENSUAL COMERCIALES'!E15-'MENSUAL COMERCIALES'!E4 -> -3790 | C6: ='MENSUAL COMERCIALES'!E26-'MENSUAL COMERCIALES'!E15 -> 3343 | D6: ='MENSUAL COMERCIALES'!E37-'MENSUAL COMERCIALES'!E26 -> -1687 | F6: 4TO TRIMESTRE | G6: ='TRIMESTRAL COMERCIALES'!E15-'TRIMESTRAL COMERCIALES'!E4 -> 17885 | H6: ='TRIMESTRAL COMERCIALES'!E26-'TRIMESTRAL COMERCIALES'!E15 -> -13517 | I6: ='TRIMESTRAL COMERCIALES'!E37-'TRIMESTRAL COMERCIALES'!E26 -> -963
A7: MAYO | B7: ='MENSUAL COMERCIALES'!F15-'MENSUAL COMERCIALES'!F4 -> -875 | C7: ='MENSUAL COMERCIALES'!F26-'MENSUAL COMERCIALES'!F15 -> 1350 | D7: ='MENSUAL COMERCIALES'!F37-'MENSUAL COMERCIALES'!F26 -> 7356
A8: JUNIO | B8: ='MENSUAL COMERCIALES'!G15-'MENSUAL COMERCIALES'!G4 -> -3483 | C8: ='MENSUAL COMERCIALES'!G26-'MENSUAL COMERCIALES'!G15 -> -300 | D8: ='MENSUAL COMERCIALES'!G37-'MENSUAL COMERCIALES'!G26 -> 2174
A9: JULIO | B9: ='MENSUAL COMERCIALES'!H15-'MENSUAL COMERCIALES'!H4 -> 1743 | C9: ='MENSUAL COMERCIALES'!H26-'MENSUAL COMERCIALES'!H15 -> -368 | D9: ='MENSUAL COMERCIALES'!H37-'MENSUAL COMERCIALES'!H26 -> -1658
A10: AGOSTO | B10: ='MENSUAL COMERCIALES'!I15-'MENSUAL COMERCIALES'!I3 -> -499 | C10: ='MENSUAL COMERCIALES'!I26-'MENSUAL COMERCIALES'!I15 -> 8724 | D10: ='MENSUAL COMERCIALES'!I37-'MENSUAL COMERCIALES'!I26 -> -9105
A11: SEPTIEMBRE | B11: ='MENSUAL COMERCIALES'!J15-'MENSUAL COMERCIALES'!J4 -> -4288 | C11: ='MENSUAL COMERCIALES'!J26-'MENSUAL COMERCIALES'!J15 -> -4207 | D11: ='MENSUAL COMERCIALES'!J37-'MENSUAL COMERCIALES'!J26 -> 5199
A12: OCTUBRE | B12: ='MENSUAL COMERCIALES'!K15-'MENSUAL COMERCIALES'!K4 -> -6186 | C12: ='MENSUAL COMERCIALES'!K26-'MENSUAL COMERCIALES'!K15 -> 513 | D12: ='MENSUAL COMERCIALES'!K37-'MENSUAL COMERCIALES'!K26 -> 1938
A13: NOVIEMBRE | B13: ='MENSUAL COMERCIALES'!L15-'MENSUAL COMERCIALES'!L4 -> 12821 | C13: ='MENSUAL COMERCIALES'!L26-'MENSUAL COMERCIALES'!L15 -> -4079 | D13: ='MENSUAL COMERCIALES'!L37-'MENSUAL COMERCIALES'!L26 -> -4568
A14: DICIEMBRE | B14: ='MENSUAL COMERCIALES'!M15-'MENSUAL COMERCIALES'!M4 -> 11250 | C14: ='MENSUAL COMERCIALES'!M26-'MENSUAL COMERCIALES'!M15 -> -9951 | D14: ='MENSUAL COMERCIALES'!M37-'MENSUAL COMERCIALES'!M26 -> 1667
A17: MENSUAL | F17: TRIMESTRAL | K17: ANUAL
A18: % | B18: 2023 | C18: 2024 | D18: 2025 | F18: % | G18: 2023 | H18: 2024 | I18: 2025 | K18: % | L18: 2023 | M18: 2024 | N18: 2025
A19: ENERO | B19: =('MENSUAL COMERCIALES'!B15-'MENSUAL COMERCIALES'!B4)/1 -> 7602 | C19: =('MENSUAL COMERCIALES'!B26-'MENSUAL COMERCIALES'!B15)/'MENSUAL COMERCIALES'!B15 -> -0.96724546 | D19: =('MENSUAL COMERCIALES'!B37-'MENSUAL COMERCIALES'!B26)/'MENSUAL COMERCIALES'!B26 -> 6.6184739 | F19: 1ER TRIMESTRE | G19: =('TRIMESTRAL COMERCIALES'!B15-'TRIMESTRAL COMERCIALES'!B4)/'TRIMESTRAL COMERCIALES'!B4 -> 0.13719494 | H19: =('TRIMESTRAL COMERCIALES'!B26-'TRIMESTRAL COMERCIALES'!B15)/'TRIMESTRAL COMERCIALES'!B15 -> -0.67060374 | I19: =('TRIMESTRAL COMERCIALES'!B37-'TRIMESTRAL COMERCIALES'!B26)/'TRIMESTRAL COMERCIALES'!B26 -> 0.39218825 | L19: =('ANUAL COMERCIALES'!C5-'ANUAL COMERCIALES'!B5)/'ANUAL COMERCIALES'!B5 -> 0.13891117 | M19: =('ANUAL COMERCIALES'!D5-'ANUAL COMERCIALES'!C5)/'ANUAL COMERCIALES'!C5 -> -0.29675288 | N19: =('ANUAL COMERCIALES'!E5-'ANUAL COMERCIALES'!D5)/'ANUAL COMERCIALES'!D5 -> 0.089818503
A20: FEBRERO | B20: =('MENSUAL COMERCIALES'!C15-'MENSUAL COMERCIALES'!C4)/'MENSUAL COMERCIALES'!C4 -> -0.6135634 | C20: =('MENSUAL COMERCIALES'!C26-'MENSUAL COMERCIALES'!C15)/'MENSUAL COMERCIALES'!C15 -> 5.2284528 | D20: =('MENSUAL COMERCIALES'!C37-'MENSUAL COMERCIALES'!C26)/'MENSUAL COMERCIALES'!C26 -> -0.9654885 | F20: 2DO TRIMESTRE | G20: =('TRIMESTRAL COMERCIALES'!C15-'TRIMESTRAL COMERCIALES'!C4)/'TRIMESTRAL COMERCIALES'!C4 -> -0.71731667 | H20: =('TRIMESTRAL COMERCIALES'!C26-'TRIMESTRAL COMERCIALES'!C15)/'TRIMESTRAL COMERCIALES'!C15 -> 1.3681096 | I20: =('TRIMESTRAL COMERCIALES'!C37-'TRIMESTRAL COMERCIALES'!C26)/'TRIMESTRAL COMERCIALES'!C26 -> 1.0314308
A21: MARZO | B21: =('MENSUAL COMERCIALES'!D15-'MENSUAL COMERCIALES'!D4)/'MENSUAL COMERCIALES'!D4 -> -0.26683116 | C21: =('MENSUAL COMERCIALES'!D26-'MENSUAL COMERCIALES'!D15)/'MENSUAL COMERCIALES'!D15 -> -1 | D21: =('MENSUAL COMERCIALES'!D37-'MENSUAL COMERCIALES'!D26)/1 -> 6593 | F21: 3ER TRIMESTRE | G21: =('TRIMESTRAL COMERCIALES'!D15-'TRIMESTRAL COMERCIALES'!D4)/'TRIMESTRAL COMERCIALES'!D4 -> -0.32577108 | H21: =('TRIMESTRAL COMERCIALES'!D26-'TRIMESTRAL COMERCIALES'!D14)/'TRIMESTRAL COMERCIALES'!D14 -> 0.4277256 | I21: =('TRIMESTRAL COMERCIALES'!D37-'TRIMESTRAL COMERCIALES'!D26)/'TRIMESTRAL COMERCIALES'!D26 -> -0.3978264
A22: ABRIL | B22: =('MENSUAL COMERCIALES'!E15-'MENSUAL COMERCIALES'!E4)/'MENSUAL COMERCIALES'!E4 -> -1 | C22: =('MENSUAL COMERCIALES'!E26-'MENSUAL COMERCIALES'!E15)/1 -> 3343 | D22: =('MENSUAL COMERCIALES'!E37-'MENSUAL COMERCIALES'!E26)/'MENSUAL COMERCIALES'!E26 -> -0.50463655 | F22: 4TO TRIMESTRE | G22: =('TRIMESTRAL COMERCIALES'!E15-'TRIMESTRAL COMERCIALES'!E4)/'TRIMESTRAL COMERCIALES'!E4 -> 1.8392637 | H22: =('TRIMESTRAL COMERCIALES'!E26-'TRIMESTRAL COMERCIALES'!E15)/'TRIMESTRAL COMERCIALES'!E15 -> -0.48958673 | I22: =('TRIMESTRAL COMERCIALES'!E37-'TRIMESTRAL COMERCIALES'!E26)/'TRIMESTRAL COMERCIALES'!E26 -> -0.068336645
A23: MAYO | B23: =('MENSUAL COMERCIALES'!F15-'MENSUAL COMERCIALES'!F4)/'MENSUAL COMERCIALES'!F4 -> -0.33967391 | C23: =('MENSUAL COMERCIALES'!F26-'MENSUAL COMERCIALES'!F15)/'MENSUAL COMERCIALES'!F15 -> 0.79365079 | D23: =('MENSUAL COMERCIALES'!F37-'MENSUAL COMERCIALES'!F26)/'MENSUAL COMERCIALES'!F26 -> 2.4110128
A24: JUNIO | B24: =('MENSUAL COMERCIALES'!G15-'MENSUAL COMERCIALES'!G4)/'MENSUAL COMERCIALES'!G4 -> -0.69757661 | C24: =('MENSUAL COMERCIALES'!G26-'MENSUAL COMERCIALES'!G15)/'MENSUAL COMERCIALES'!G15 -> -0.1986755 | D24: =('MENSUAL COMERCIALES'!G37-'MENSUAL COMERCIALES'!G26)/'MENSUAL COMERCIALES'!G26 -> 1.7966942
A25: JULIO | B25: =('MENSUAL COMERCIALES'!H15-'MENSUAL COMERCIALES'!H4)/'MENSUAL COMERCIALES'!H4 -> 0.83838384 | C25: =('MENSUAL COMERCIALES'!H26-'MENSUAL COMERCIALES'!H15)/'MENSUAL COMERCIALES'!H15 -> -0.096284668 | D25: =('MENSUAL COMERCIALES'!H37-'MENSUAL COMERCIALES'!H26)/'MENSUAL COMERCIALES'!H26 -> -0.48002316
A26: AGOSTO | B26: =('MENSUAL COMERCIALES'!I15-'MENSUAL COMERCIALES'!I4)/'MENSUAL COMERCIALES'!I4 -> -0.61572783 | C26: =('MENSUAL COMERCIALES'!I26-'MENSUAL COMERCIALES'!I15)/'MENSUAL COMERCIALES'!I15 -> 6.3309144 | D26: =('MENSUAL COMERCIALES'!I37-'MENSUAL COMERCIALES'!I26)/'MENSUAL COMERCIALES'!I26 -> -0.90130667
A27: SEPTIEMBRE | B27: =('MENSUAL COMERCIALES'!J15-'MENSUAL COMERCIALES'!J4)/'MENSUAL COMERCIALES'!J4 -> -0.48044818 | C27: =('MENSUAL COMERCIALES'!J26-'MENSUAL COMERCIALES'!J15)/'MENSUAL COMERCIALES'!J15 -> -0.90726763 | D27: =('MENSUAL COMERCIALES'!J37-'MENSUAL COMERCIALES'!J26)/'MENSUAL COMERCIALES'!J26 -> 12.090698
A28: OCTUBRE | B28: =('MENSUAL COMERCIALES'!K15-'MENSUAL COMERCIALES'!K4)/'MENSUAL COMERCIALES'!K4 -> -0.88069476 | C28: =('MENSUAL COMERCIALES'!K26-'MENSUAL COMERCIALES'!K15)/'MENSUAL COMERCIALES'!K15 -> 0.61217184 | D28: =('MENSUAL COMERCIALES'!K37-'MENSUAL COMERCIALES'!K26)/'MENSUAL COMERCIALES'!K26 -> 1.434493
A29: NOVIEMBRE | B29: =('MENSUAL COMERCIALES'!L15-'MENSUAL COMERCIALES'!L4)/'MENSUAL COMERCIALES'!L4 -> 5.83303 | C29: =('MENSUAL COMERCIALES'!L26-'MENSUAL COMERCIALES'!L15)/'MENSUAL COMERCIALES'!L15 -> -0.27158932 | D29: =('MENSUAL COMERCIALES'!L37-'MENSUAL COMERCIALES'!L26)/'MENSUAL COMERCIALES'!L26 -> -0.41755027
A30: DICIEMBRE | B30: =('MENSUAL COMERCIALES'!M15-'MENSUAL COMERCIALES'!M4)/'MENSUAL COMERCIALES'!M4 -> 22.410359 | C30: =('MENSUAL COMERCIALES'!I30-'MENSUAL COMERCIALES'!I19)/'MENSUAL COMERCIALES'!I19 -> 1.0649888 | D30: =('MENSUAL COMERCIALES'!M37-'MENSUAL COMERCIALES'!M26)/'MENSUAL COMERCIALES'!M26 -> 0.92559689

Sheet ANTONIO
A1: MENSUAL | F1: TRIMESTRAL | K1: ANUAL
A2: NUMÉRICO | B2: 2023 | C2: 2024 | D2: 2025 | F2: NUMÉRICO | G2: 2023 | H2: 2024 | I2: 2025 | K2: NUMÉRICO | L2: 2023 | M2: 2024 | N2: 2025
A3: ENERO | B3: ='MENSUAL COMERCIALES'!B16-'MENSUAL COMERCIALES'!B5 -> 12794 | C3: ='MENSUAL COMERCIALES'!B27-'MENSUAL COMERCIALES'!B16 -> -4772 | D3: ='MENSUAL COMERCIALES'!B38-'MENSUAL COMERCIALES'!B27 -> -4426 | F3: 1ER TRIMESTRE | G3: ='TRIMESTRAL COMERCIALES'!B16-'TRIMESTRAL COMERCIALES'!B5 -> -48 | H3: ='TRIMESTRAL COMERCIALES'!B27-'TRIMESTRAL COMERCIALES'!B16 -> -21102 | I3: ='TRIMESTRAL COMERCIALES'!B38-'TRIMESTRAL COMERCIALES'!B27 -> -2960 | L3: ='ANUAL COMERCIALES'!C6-'ANUAL COMERCIALES'!B6 -> -40194 | M3: ='ANUAL COMERCIALES'!D6-'ANUAL COMERCIALES'!C6 -> -4208 | N3: ='ANUAL COMERCIALES'!E6-'ANUAL COMERCIALES'!D6 -> -21844
A4: FEBRERO | B4: ='MENSUAL COMERCIALES'!C16-'MENSUAL COMERCIALES'!C5 -> -12718 | C4: ='MENSUAL COMERCIALES'!C27-'MENSUAL COMERCIALES'!C16 -> -1786 | D4: ='MENSUAL COMERCIALES'!C38-'MENSUAL COMERCIALES'!C27 -> -3471 | F4: 2DO TRIMESTRE | G4: ='TRIMESTRAL COMERCIALES'!C16-'TRIMESTRAL COMERCIALES'!C5 -> -25523 | H4: ='TRIMESTRAL COMERCIALES'!C27-'TRIMESTRAL COMERCIALES'!C16 -> 15240 | I4: ='TRIMESTRAL COMERCIALES'!C38-'TRIMESTRAL COMERCIALES'!C27 -> -7085
A5: MARZO | B5: ='MENSUAL COMERCIALES'!D16-'MENSUAL COMERCIALES'!D5 -> -124 | C5: ='MENSUAL COMERCIALES'!D27-'MENSUAL COMERCIALES'!D16 -> -14544 | D5: ='MENSUAL COMERCIALES'!D38-'MENSUAL COMERCIALES'!D27 -> 4937 | F5: 3ER TRIMESTRE | G5: ='TRIMESTRAL COMERCIALES'!D16-Tabla2[[#This Row],[3ER TRIMESTRE]] -> -3094 | H5: ='TRIMESTRAL COMERCIALES'!D27-'TRIMESTRAL COMERCIALES'!D16 -> 1488 | I5: ='TRIMESTRAL COMERCIALES'!D38-'TRIMESTRAL COMERCIALES'!D27 -> -5395
A6: ABRIL | B6: ='MENSUAL COMERCIALES'!E16-'MENSUAL COMERCIALES'!E5 -> -4469 | C6: ='MENSUAL COMERCIALES'!E27-'MENSUAL COMERCIALES'!E16 -> 6710 | D6: ='MENSUAL COMERCIALES'!E38-'MENSUAL COMERCIALES'!E27 -> -5489 | F6: 4TO TRIMESTRE | G6: ='TRIMESTRAL COMERCIALES'!E16-'TRIMESTRAL COMERCIALES'!E5 -> -11529 | H6: ='TRIMESTRAL COMERCIALES'!E27-'TRIMESTRAL COMERCIALES'!E16 -> 166 | I6: ='TRIMESTRAL COMERCIALES'!E38-'TRIMESTRAL COMERCIALES'!E27 -> -6404
A7: MAYO | B7: ='MENSUAL COMERCIALES'!F16-'MENSUAL COMERCIALES'!F5 -> -17935 | C7: ='MENSUAL COMERCIALES'!F27-'MENSUAL COMERCIALES'!F16 -> 4496 | D7: ='MENSUAL COMERCIALES'!F38-'MENSUAL COMERCIALES'!F27 -> -8347
A8: JUNIO | B8: ='MENSUAL COMERCIALES'!G16-'MENSUAL COMERCIALES'!G5 -> -3119 | C8: ='MENSUAL COMERCIALES'!G27-'MENSUAL COMERCIALES'!G16 -> 4034 | D8: ='MENSUAL COMERCIALES'!G38-'MENSUAL COMERCIALES'!G27 -> 6751
A9: JULIO | B9: ='MENSUAL COMERCIALES'!H16-'MENSUAL COMERCIALES'!H5 -> -11096 | C9: ='MENSUAL COMERCIALES'!H27-'MENSUAL COMERCIALES'!H16 -> 9673 | D9: ='MENSUAL COMERCIALES'!H38-'MENSUAL COMERCIALES'!H27 -> -5678
A10: AGOSTO | B10: ='MENSUAL COMERCIALES'!I16-'MENSUAL COMERCIALES'!I5 -> 3594 | C10: ='MENSUAL COMERCIALES'!I27-'MENSUAL COMERCIALES'!I16 -> -7176 | D10: ='MENSUAL COMERCIALES'!I38-'MENSUAL COMERCIALES'!I27 -> -1470
A11: SEPTIEMBRE | B11: ='MENSUAL COMERCIALES'!J16-'MENSUAL COMERCIALES'!J5 -> 4408 | C11: ='MENSUAL COMERCIALES'!J27-'MENSUAL COMERCIALES'!J16 -> -1009 | D11: ='MENSUAL COMERCIALES'!J38-'MENSUAL COMERCIALES'!J27 -> 1753
A12: OCTUBRE | B12: ='MENSUAL COMERCIALES'!K16-'MENSUAL COMERCIALES'!K5 -> -4612 | C12: ='MENSUAL COMERCIALES'!K27-'MENSUAL COMERCIALES'!K16 -> 5597 | D12: ='MENSUAL COMERCIALES'!K38-'MENSUAL COMERCIALES'!K27 -> -3749
A13: NOVIEMBRE | B13: ='MENSUAL COMERCIALES'!L16-'MENSUAL COMERCIALES'!L5 -> -5812 | C13: ='MENSUAL COMERCIALES'!L27-'MENSUAL COMERCIALES'!L16 -> -4225 | D13: ='MENSUAL COMERCIALES'!L38-'MENSUAL COMERCIALES'!L27 -> -706
A14: DICIEMBRE | B14: ='MENSUAL COMERCIALES'!M16-'MENSUAL COMERCIALES'!M5 -> -1105 | C14: ='MENSUAL COMERCIALES'!M27-'MENSUAL COMERCIALES'!M16 -> -1206 | D14: ='MENSUAL COMERCIALES'!M38-'MENSUAL COMERCIALES'!M27 -> -1949
A17: MENSUAL | F17: TRIMESTRAL | K17: ANUAL
A18: % | B18: 2023 | C18: 2024 | D18: 2025 | F18: % | G18: 2023 | H18: 2024 | I18: 2025 | K18: % | L18: 2023 | M18: 2024 | N18: 2025
A19: ENERO | B19: =('MENSUAL COMERCIALES'!B16-'MENSUAL COMERCIALES'!B5)/'MENSUAL COMERCIALES'!B5 -> 16.072864 | C19: =('MENSUAL COMERCIALES'!B27-'MENSUAL COMERCIALES'!B16)/'MENSUAL COMERCIALES'!B16 -> -0.35114054 | D19: =('MENSUAL COMERCIALES'!B38-'MENSUAL COMERCIALES'!B27)/'MENSUAL COMERCIALES'!B27 -> -0.50192787 | F19: 1ER TRIMESTRE | G19: =('TRIMESTRAL COMERCIALES'!B16-'TRIMESTRAL COMERCIALES'!B5)/'TRIMESTRAL COMERCIALES'!B5 -> -0.0013184278 | H19: =('TRIMESTRAL COMERCIALES'!B27-'TRIMESTRAL COMERCIALES'!B16)/'TRIMESTRAL COMERCIALES'!B16 -> -0.580379 | I19: =('TRIMESTRAL COMERCIALES'!B38-'TRIMESTRAL COMERCIALES'!B27)/'TRIMESTRAL COMERCIALES'!B27 -> -0.19400931 | L19: =('ANUAL COMERCIALES'!C6-'ANUAL COMERCIALES'!B6)/'ANUAL COMERCIALES'!B6 -> -0.27762697 | M19: =('ANUAL COMERCIALES'!D6-'ANUAL COMERCIALES'!C6)/'ANUAL COMERCIALES'!C6 -> -0.040235985 | N19: =('ANUAL COMERCIALES'!E6-'ANUAL COMERCIALES'!D6)/'ANUAL COMERCIALES'!D6 -> -0.21762391
A20: FEBRERO | B20: =('MENSUAL COMERCIALES'!C16-'MENSUAL COMERCIALES'!C5)/'MENSUAL COMERCIALES'!C5 -> -0.66729629 | C20: =('MENSUAL COMERCIALES'!C27-'MENSUAL COMERCIALES'!C16)/'MENSUAL COMERCIALES'!C16 -> -0.28165904 | D20: =('MENSUAL COMERCIALES'!C38-'MENSUAL COMERCIALES'!C27)/'MENSUAL COMERCIALES'!C27 -> -0.76201976 | F20: 2DO TRIMESTRE | G20: =('TRIMESTRAL COMERCIALES'!C16-'TRIMESTRAL COMERCIALES'!C5)/'TRIMESTRAL COMERCIALES'!C5 -> -0.64241128 | H20: =('TRIMESTRAL COMERCIALES'!C27-'TRIMESTRAL COMERCIALES'!C16)/'TRIMESTRAL COMERCIALES'!C16 -> 1.0727106 | I20: =('TRIMESTRAL COMERCIALES'!C38-'TRIMESTRAL COMERCIALES'!C27)/'TRIMESTRAL COMERCIALES'!C27 -> -0.24060176
A21: MARZO | B21: =('MENSUAL COMERCIALES'!D16-'MENSUAL COMERCIALES'!D5)/'MENSUAL COMERCIALES'!D5 -> -0.0074915418 | C21: =('MENSUAL COMERCIALES'!D27-'MENSUAL COMERCIALES'!D16)/'MENSUAL COMERCIALES'!D16 -> -0.88531775 | D21: =('MENSUAL COMERCIALES'!D38-'MENSUAL COMERCIALES'!D27)/'MENSUAL COMERCIALES'!D27 -> 2.6204883 | F21: 3ER TRIMESTRE | G21: =('TRIMESTRAL COMERCIALES'!D16-'TRIMESTRAL COMERCIALES'!D5)/'TRIMESTRAL COMERCIALES'!D5 -> -0.097094081 | H21: =('TRIMESTRAL COMERCIALES'!D27-'TRIMESTRAL COMERCIALES'!D16)/'TRIMESTRAL COMERCIALES'!D16 -> 0.051716947 | I21: =('TRIMESTRAL COMERCIALES'!D38-'TRIMESTRAL COMERCIALES'!D27)/'TRIMESTRAL COMERCIALES'!D27 -> -0.17828817
A22: ABRIL | B22: =('MENSUAL COMERCIALES'!E16-'MENSUAL COMERCIALES'!E5)/'MENSUAL COMERCIALES'!E5 -> -0.64777504 | C22: =('MENSUAL COMERCIALES'!E27-'MENSUAL COMERCIALES'!E16)/'MENSUAL COMERCIALES'!E16 -> 2.7613169 | D22: =('MENSUAL COMERCIALES'!E38-'MENSUAL COMERCIALES'!E27)/'MENSUAL COMERCIALES'!E27 -> -0.60054705 | F22: 4TO TRIMESTRE | G22: =('TRIMESTRAL COMERCIALES'!E16-'TRIMESTRAL COMERCIALES'!E5)/'TRIMESTRAL COMERCIALES'!E5 -> -0.31350954 | H22: =('TRIMESTRAL COMERCIALES'!E27-'TRIMESTRAL COMERCIALES'!E16)/'TRIMESTRAL COMERCIALES'!E16 -> 0.0065755595 | I22: =('TRIMESTRAL COMERCIALES'!E38-'TRIMESTRAL COMERCIALES'!E27)/'TRIMESTRAL COMERCIALES'!E27 -> -0.25201684
A23: MAYO | B23: =('MENSUAL COMERCIALES'!F16-'MENSUAL COMERCIALES'!F5)/'MENSUAL COMERCIALES'!F5 -> -0.71878006 | C23: =('MENSUAL COMERCIALES'!F27-'MENSUAL COMERCIALES'!F16)/'MENSUAL COMERCIALES'!F16 -> 0.64072966 | D23: =('MENSUAL COMERCIALES'!F38-'MENSUAL COMERCIALES'!F27)/'MENSUAL COMERCIALES'!F27 -> -0.72500651
A24: JUNIO | B24: =('MENSUAL COMERCIALES'!G16-'MENSUAL COMERCIALES'!G5)/'MENSUAL COMERCIALES'!G5 -> -0.39586242 | C24: =('MENSUAL COMERCIALES'!G27-'MENSUAL COMERCIALES'!G16)/'MENSUAL COMERCIALES'!G16 -> 0.84747899 | D24: =('MENSUAL COMERCIALES'!G38-'MENSUAL COMERCIALES'!G27)/'MENSUAL COMERCIALES'!G27 -> 0.76768251
A25: JULIO | B25: =('MENSUAL COMERCIALES'!H16-'MENSUAL COMERCIALES'!H5)/'MENSUAL COMERCIALES'!H5 -> -0.82596397 | C25: =('MENSUAL COMERCIALES'!H27-'MENSUAL COMERCIALES'!H16)/'MENSUAL COMERCIALES'!H16 -> 4.1372968 | D25: =('MENSUAL COMERCIALES'!H38-'MENSUAL COMERCIALES'!H27)/'MENSUAL COMERCIALES'!H27 -> -0.47273333
A26: AGOSTO | B26: =('MENSUAL COMERCIALES'!I16-'MENSUAL COMERCIALES'!I5)/'MENSUAL COMERCIALES'!I5 -> 0.25781923 | C26: =('MENSUAL COMERCIALES'!I27-'MENSUAL COMERCIALES'!I16)/'MENSUAL COMERCIALES'!I16 -> -0.40926201 | D26: =('MENSUAL COMERCIALES'!I38-'MENSUAL COMERCIALES'!I27)/'MENSUAL COMERCIALES'!I27 -> -0.14191929
A27: SEPTIEMBRE | B27: =('MENSUAL COMERCIALES'!J16-'MENSUAL COMERCIALES'!J5)/'MENSUAL COMERCIALES'!J5 -> 0.98130009 | C27: =('MENSUAL COMERCIALES'!J27-'MENSUAL COMERCIALES'!J16)/'MENSUAL COMERCIALES'!J16 -> -0.11337079 | D27: =('MENSUAL COMERCIALES'!J38-Tabla6[[#This Row],[SEPTIEMBRE]])/Tabla6[[#This Row],[SEPTIEMBRE]] -> 0.22215182
A28: OCTUBRE | B28: =('MENSUAL COMERCIALES'!K16-'MENSUAL COMERCIALES'!K5)/'MENSUAL COMERCIALES'!K5 -> -0.30292282 | C28: =('MENSUAL COMERCIALES'!K27-'MENSUAL COMERCIALES'!K16)/'MENSUAL COMERCIALES'!K16 -> 0.52737209 | D28: =('MENSUAL COMERCIALES'!K38-'MENSUAL COMERCIALES'!K27)/'MENSUAL COMERCIALES'!K27 -> -0.23127699
A29: NOVIEMBRE | B29: =('MENSUAL COMERCIALES'!L16-'MENSUAL COMERCIALES'!L5)/'MENSUAL COMERCIALES'!L5 -> -0.42290621 | C29: =('MENSUAL COMERCIALES'!L27-'MENSUAL COMERCIALES'!L16)/'MENSUAL COMERCIALES'!L16 -> -0.53271971 | D29: =('MENSUAL COMERCIALES'!L38-'MENSUAL COMERCIALES'!L27)/'MENSUAL COMERCIALES'!L27 -> -0.19050189
A30: DICIEMBRE | B30: =('MENSUAL COMERCIALES'!M16-'MENSUAL COMERCIALES'!M5)/'MENSUAL COMERCIALES'!M5 -> -0.14155778 | C30: =('MENSUAL COMERCIALES'!M27-'MENSUAL COMERCIALES'!M16)/'MENSUAL COMERCIALES'!M16 -> -0.17997314 | D30: =('MENSUAL COMERCIALES'!M38-'MENSUAL COMERCIALES'!M27)/'MENSUAL COMERCIALES'!M27 -> -0.35468608

Sheet ÁNGEL
A1: MENSUAL | F1: TRIMESTRAL | K1: ANUAL
A2: NUMÉRICO | B2: 2023 | C2: 2024 | D2: 2025 | F2: NUMÉRICO | G2: 2023 | H2: 2024 | I2: 2025 | K2: NUMÉRICO | L2: 2023 | M2: 2024 | N2: 2025
A3: ENERO | B3: ='MENSUAL COMERCIALES'!B17-'MENSUAL COMERCIALES'!B6 -> 26678 | C3: ='MENSUAL COMERCIALES'!B28-'MENSUAL COMERCIALES'!B17 -> -9645 | D3: ='MENSUAL COMERCIALES'!B39-'MENSUAL COMERCIALES'!B28 -> -8219 | F3: 1ER TRIMESTRE | G3: ='TRIMESTRAL COMERCIALES'!B17-'TRIMESTRAL COMERCIALES'!B6 -> 22181 | H3: ='TRIMESTRAL COMERCIALES'!B28-'TRIMESTRAL COMERCIALES'!B17 -> -27751 | I3: ='TRIMESTRAL COMERCIALES'!B39-'TRIMESTRAL COMERCIALES'!B28 -> -8870 | L3: ='ANUAL COMERCIALES'!C7-'ANUAL COMERCIALES'!B7 -> -842 | M3: ='ANUAL COMERCIALES'!D7-'ANUAL COMERCIALES'!C7 -> -45380 | N3: ='ANUAL COMERCIALES'!E7-'ANUAL COMERCIALES'!D7 -> -87913
A4: FEBRERO | B4: ='MENSUAL COMERCIALES'!C17-'MENSUAL COMERCIALES'!C6 -> -14621 | C4: ='MENSUAL COMERCIALES'!C28-'MENSUAL COMERCIALES'!C17 -> -6044 | D4: ='MENSUAL COMERCIALES'!C39-'MENSUAL COMERCIALES'!C28 -> -9088 | F4: 2DO TRIMESTRE | G4: ='TRIMESTRAL COMERCIALES'!C17-'TRIMESTRAL COMERCIALES'!C6 -> -24077 | H4: ='TRIMESTRAL COMERCIALES'!C28-'TRIMESTRAL COMERCIALES'!C17 -> -1192 | I4: ='TRIMESTRAL COMERCIALES'!C39-'TRIMESTRAL COMERCIALES'!C28 -> -21810
A5: MARZO | B5: ='MENSUAL COMERCIALES'!D17-'MENSUAL COMERCIALES'!D6 -> 10124 | C5: ='MENSUAL COMERCIALES'!D28-'MENSUAL COMERCIALES'!D17 -> -12062 | D5: ='MENSUAL COMERCIALES'!D39-'MENSUAL COMERCIALES'!D28 -> 8437 | F5: 3ER TRIMESTRE | G5: ='TRIMESTRAL COMERCIALES'!D17-'TRIMESTRAL COMERCIALES'!D6 -> 7324 | H5: ='TRIMESTRAL COMERCIALES'!D28-'TRIMESTRAL COMERCIALES'!D17 -> -18341 | I5: ='TRIMESTRAL COMERCIALES'!D39-'TRIMESTRAL COMERCIALES'!D28 -> -22093
A6: ABRIL | B6: ='MENSUAL COMERCIALES'!E17-'MENSUAL COMERCIALES'!E6 -> -7740 | C6: ='MENSUAL COMERCIALES'!E28-'MENSUAL COMERCIALES'!E17 -> -5721 | D6: ='MENSUAL COMERCIALES'!E39-'MENSUAL COMERCIALES'!E28 -> -3180 | F6: 4TO TRIMESTRE | G6: ='TRIMESTRAL COMERCIALES'!E17-'TRIMESTRAL COMERCIALES'!E6 -> -6270 | H6: ='TRIMESTRAL COMERCIALES'!E28-'TRIMESTRAL COMERCIALES'!E17 -> 1904 | I6: ='TRIMESTRAL COMERCIALES'!E39-'TRIMESTRAL COMERCIALES'!E28 -> -35140
A7: MAYO | B7: ='MENSUAL COMERCIALES'!F17-'MENSUAL COMERCIALES'!F6 -> -1891 | C7: ='MENSUAL COMERCIALES'!F28-'MENSUAL COMERCIALES'!F17 -> 11762 | D7: ='MENSUAL COMERCIALES'!F39-'MENSUAL COMERCIALES'!F28 -> -17268
A8: JUNIO | B8: ='MENSUAL COMERCIALES'!G17-'MENSUAL COMERCIALES'!G6 -> -14446 | C8: ='MENSUAL COMERCIALES'!G28-'MENSUAL COMERCIALES'!G17 -> -7233 | D8: ='MENSUAL COMERCIALES'!G39-'MENSUAL COMERCIALES'!G28 -> -1362
A9: JULIO | B9: ='MENSUAL COMERCIALES'!H17-'MENSUAL COMERCIALES'!H6 -> 803 | C9: ='MENSUAL COMERCIALES'!H28-'MENSUAL COMERCIALES'!H17 -> -3524 | D9: ='MENSUAL COMERCIALES'!H39-'MENSUAL COMERCIALES'!H28 -> -6951
A10: AGOSTO | B10: ='MENSUAL COMERCIALES'!I18-'MENSUAL COMERCIALES'!I7 -> -3454 | C10: ='MENSUAL COMERCIALES'!I28-'MENSUAL COMERCIALES'!I17 -> -1201 | D10: ='MENSUAL COMERCIALES'!I39-'MENSUAL COMERCIALES'!I28 -> -9826
A11: SEPTIEMBRE | B11: ='MENSUAL COMERCIALES'!J18-'MENSUAL COMERCIALES'!J7 -> -4802 | C11: ='MENSUAL COMERCIALES'!J28-'MENSUAL COMERCIALES'!J17 -> -13616 | D11: ='MENSUAL COMERCIALES'!J39-'MENSUAL COMERCIALES'!J28 -> -5316
A12: OCTUBRE | B12: ='MENSUAL COMERCIALES'!K18-'MENSUAL COMERCIALES'!K7 -> -2832 | C12: ='MENSUAL COMERCIALES'!K28-'MENSUAL COMERCIALES'!K17 -> -5985 | D12: ='MENSUAL COMERCIALES'!K39-'MENSUAL COMERCIALES'!K28 -> -11125
A13: NOVIEMBRE | B13: ='MENSUAL COMERCIALES'!L18-'MENSUAL COMERCIALES'!L7 -> 4640 | C13: ='MENSUAL COMERCIALES'!L28-'MENSUAL COMERCIALES'!L17 -> 5935 | D13: ='MENSUAL COMERCIALES'!L39-'MENSUAL COMERCIALES'!L28 -> -15303
A14: DICIEMBRE | B14: ='MENSUAL COMERCIALES'!M18-'MENSUAL COMERCIALES'!M7 -> 4012 | C14: ='MENSUAL COMERCIALES'!M28-'MENSUAL COMERCIALES'!M17 -> 1954 | D14: ='MENSUAL COMERCIALES'!M39-'MENSUAL COMERCIALES'!M28 -> -8712
A17: MENSUAL | F17: TRIMESTRAL | K17: ANUAL
A18: % | B18: 2023 | C18: 2024 | D18: 2025 | F18: % | G18: 2023 | H18: 2024 | I18: 2025 | K18: % | L18: 2023 | M18: 2024 | N18: 2025
